Workbook
Name agua_consumo: #REF!
Name agua_consumo: #REF!
Name pp_anual26: #REF!
Name pp_anual26: #REF!

Sheet tabla
A1: anexo
A2: 2026-01
A3: 2026-02
A4: 2026-03
A5: 2026-04
A6: 2026-05
A7: 2026-06
A8: 2026-07
A9: 2026-08
A10: 2026-09
A11: 2026-10
A12: 2026-11
... A20: sin identificar

Sheet pres
B2: PRESUPUESTO X DISTRIBUIR | C2: 60116
B4: agua potable 2026-01 | C4: =5908.3-1200 -> 4708.3
C5: =SUM(C2:C4) -> 64824.3

Sheet consumo_agua
H1: recibo | I1: 4713.4 | L1: 4636.5 | O1: 5266.7 | R1: 2972.4 | U1: 3793.1 | X1: 3876.4 | AA1: 4708.3
H2: m3 conteo | I2: =$G$203 -> 1262.229 | J2: <promedio | L2: =J203 -> 1115.961 | M2: <promedio | O2: =M203 -> 824.779 | P2: <promedio | R2: =P203 -> 1035.538 | U2: =S203 -> 1272.95 | X2: =V203 -> 1302.895 | AA2: =Y203 -> 1519.337
H3: c.u. x m3 | I3: =ROUND(I1/I2,4) -> 3.7342 | L3: =ROUND(L1/L2,4) -> 4.1547 | O3: =ROUND(O1/O2,4) -> 6.3856 | R3: =ROUND(R1/R2,4) -> 2.8704 | U3: =ROUND(U1/U2,4) -> 2.9798 | X3: =ROUND(X1/X2,4) -> 2.9752 | AA3: =ROUND(AA1/AA2,4) -> 3.0989
A4: JUNTA DE PROPIETARIOS DEL EDIFICIO MULTIFAMILIAR " PACIFIK OCEAN TOWER"
A5: Historico - consumo de agua
A7: DEPAF | B7: MAYO | C7: consumo> | D7: JUNIO | E7: consumo> | F7: JULIO | G7: consumo> | H7: AGOSTO | I7: PEN-agua | J7: consumo> | K7: SET | L7: PEN-agua | M7: consumo> | N7: OCT | O7: PEN-agua | P7: consumo> | Q7: NOV | R7: PEN-agua | S7: consumo> | T7: DIC | U7: PEN-agua | V7: consumo> | W7: 46023 | X7: PEN-agua | Y7: consumo> | Z7: 46054 | AA7: PEN-agua
A8: DEPA-101 | B8: 800 | C8: =D8-B8 -> 21 | D8: 821 | E8: =F8-D8 -> 22 | F8: 843 | G8: =H8-F8 -> 27 | H8: 870 | I8: =ROUND(G8*$I$3,2) -> 100.82 | J8: =K8-H8 -> 23 | K8: 893 | L8: =ROUND(J8*$L$3,2) -> 95.56 | M8: =N8-K8 -> 18 | N8: 911 | O8: =ROUND(M8*$O$3,2) -> 114.94 | P8: =Q8-N8 -> 19 | Q8: 930 | R8: =ROUND(P8*$R$3,2) -> 54.54 | S8: =+T8-Q8 -> 22 | T8: 952 | U8: =ROUND(S8*$U$3,2) -> 65.56 | V8: =+W8-T8 -> 24 | W8: 976 | X8: =V8*$X$3 -> 71.4048 | Y8: =+Z8-W8 -> 23 | Z8: 999 | AA8: =ROUND(Y8*$AA$3,2) -> 71.27
A9: DEPA-102 | B9: 287 | C9: =D9-B9 -> 7 | D9: 294 | E9: =F9-D9 -> 4 | F9: 298 | G9: =H9-F9 -> 7 | H9: 305 | I9: =ROUND(G9*$I$3,2) -> 26.14 | J9: =K9-H9 -> 4 | K9: 309 | L9: =ROUND(J9*$L$3,2) -> 16.62 | M9: =N9-K9 -> 3 | N9: 312 | O9: =ROUND(M9*$O$3,2) -> 19.16 | P9: =Q9-N9 -> 3 | Q9: 315 | R9: =ROUND(P9*$R$3,2) -> 8.61 | S9: =+T9-Q9 -> 2 | T9: 317 | U9: =ROUND(S9*$U$3,2) -> 5.96 | V9: =+W9-T9 -> 2 | W9: 319 | X9: =V9*$X$3 -> 5.9504 | Y9: =+Z9-W9 -> 4 | Z9: 323 | AA9: =ROUND(Y9*$AA$3,2) -> 12.4
A10: DEPA-103 | B10: 51 | C10: =D10-B10 -> 0 | D10: 51 | E10: =F10-D10 -> 0 | F10: 51 | G10: =H10-F10 -> 0 | H10: 51 | I10: =ROUND(G10*$I$3,2) -> 0 | J10: =K10-H10 -> 0 | K10: 51 | L10: =ROUND(J10*$L$3,2) -> 0 | M10: =N10-K10 -> 0 | N10: 51 | O10: =ROUND(M10*$O$3,2) -> 0 | P10: =Q10-N10 -> 0 | Q10: 51 | R10: =ROUND(P10*$R$3,2) -> 0 | S10: =+T10-Q10 -> 0 | T10: 51 | U10: =ROUND(S10*$U$3,2) -> 0 | V10: =+W10-T10 -> 0 | W10: 51 | X10: =V10*$X$3 -> 0 | Y10: =+Z10-W10 -> 0 | Z10: 51 | AA10: =ROUND(Y10*$AA$3,2) -> 0
A11: DEPA-104 | B11: 327 | C11: =D11-B11 -> 5 | D11: 332 | E11: =F11-D11 -> 6 | F11: 338 | G11: =H11-F11 -> 7 | H11: 345 | I11: =ROUND(G11*$I$3,2) -> 26.14 | J11: =K11-H11 -> 5 | K11: 350 | L11: =ROUND(J11*$L$3,2) -> 20.77 | M11: =N11-K11 -> 5 | N11: 355 | O11: =ROUND(M11*$O$3,2) -> 31.93 | P11: =Q11-N11 -> 9 | Q11: 364 | R11: =ROUND(P11*$R$3,2) -> 25.83 | S11: =+T11-Q11 -> 8 | T11: 372 | U11: =ROUND(S11*$U$3,2) -> 23.84 | V11: =+W11-T11 -> 12 | W11: 384 | X11: =V11*$X$3 -> 35.7024 | Y11: =+Z11-W11 -> 12 | Z11: 396 | AA11: =ROUND(Y11*$AA$3,2) -> 37.19
A12: DEPA-105 | B12: 532 | C12: =D12-B12 -> 10 | D12: 542 | E12: =F12-D12 -> 12 | F12: 554 | G12: =H12-F12 -> 8 | H12: 562 | I12: =ROUND(G12*$I$3,2) -> 29.87 | J12: =K12-H12 -> 13 | K12: 575 | L12: =ROUND(J12*$L$3,2) -> 54.01 | M12: =N12-K12 -> 10 | N12: 585 | O12: =ROUND(M12*$O$3,2) -> 63.86 | P12: =Q12-N12 -> 14 | Q12: 599 | R12: =ROUND(P12*$R$3,2) -> 40.19 | S12: =+T12-Q12 -> 13 | T12: 612 | U12: =ROUND(S12*$U$3,2) -> 38.74 | V12: =+W12-T12 -> 22 | W12: 634 | X12: =V12*$X$3 -> 65.4544 | Y12: =+Z12-W12 -> 14 | Z12: 648 | AA12: =ROUND(Y12*$AA$3,2) -> 43.38
A13: DEPA-106 | B13: 396 | C13: =D13-B13 -> 0 | D13: 396 | E13: =F13-D13 -> 0 | F13: 396 | G13: =H13-F13 -> 1 | H13: 397 | I13: =ROUND(G13*$I$3,2) -> 3.73 | J13: =K13-H13 -> 2 | K13: 399 | L13: =ROUND(J13*$L$3,2) -> 8.31 | M13: =N13-K13 -> 5 | N13: 404 | O13: =ROUND(M13*$O$3,2) -> 31.93 | P13: =Q13-N13 -> 8 | Q13: 412 | R13: =ROUND(P13*$R$3,2) -> 22.96 | S13: =+T13-Q13 -> 9 | T13: 421 | U13: =ROUND(S13*$U$3,2) -> 26.82 | V13: =+W13-T13 -> 8 | W13: 429 | X13: =V13*$X$3 -> 23.8016 | Y13: =+Z13-W13 -> 9 | Z13: 438 | AA13: =ROUND(Y13*$AA$3,2) -> 27.89
A14: DEPA-107 | B14: 25 | C14: =D14-B14 -> 0 | D14: 25 | E14: =F14-D14 -> 1 | F14: 26 | G14: =H14-F14 -> 0 | H14: 26 | I14: =ROUND(G14*$I$3,2) -> 0 | J14: =K14-H14 -> 0 | K14: 26 | L14: =ROUND(J14*$L$3,2) -> 0 | M14: =N14-K14 -> 1 | N14: 27 | O14: =ROUND(M14*$O$3,2) -> 6.39 | P14: =Q14-N14 -> 1 | Q14: 28 | R14: =ROUND(P14*$R$3,2) -> 2.87 | S14: =+T14-Q14 -> 0 | T14: 28 | U14: =ROUND(S14*$U$3,2) -> 0 | V14: =+W14-T14 -> 1 | W14: 29 | X14: =V14*$X$3 -> 2.9752 | Y14: =+Z14-W14 -> 0 | Z14: 29 | AA14: =ROUND(Y14*$AA$3,2) -> 0
A15: DEPA-201 | B15: 128 | C15: =D15-B15 -> 8 | D15: 136 | E15: =F15-D15 -> 6 | F15: 142 | G15: =H15-F15 -> 11 | H15: 153 | I15: =ROUND(G15*$I$3,2) -> 41.08 | J15: =K15-H15 -> 8 | K15: 161 | L15: =ROUND(J15*$L$3,2) -> 33.24 | M15: =N15-K15 -> 4 | N15: 165 | O15: =ROUND(M15*$O$3,2) -> 25.54 | P15: =Q15-N15 -> 6 | Q15: 171 | R15: =ROUND(P15*$R$3,2) -> 17.22 | S15: =+T15-Q15 -> 9 | T15: 180 | U15: =ROUND(S15*$U$3,2) -> 26.82 | V15: =+W15-T15 -> 11 | W15: 191 | X15: =V15*$X$3 -> 32.7272 | Y15: =+Z15-W15 -> 9 | Z15: 200 | AA15: =ROUND(Y15*$AA$3,2) -> 27.89
A16: DEPA-202 | B16: 95 | C16: =D16-B16 -> 6 | D16: 101 | E16: =F16-D16 -> 4 | F16: 105 | G16: =H16-F16 -> 6 | H16: 111 | I16: =ROUND(G16*$I$3,2) -> 22.41 | J16: =K16-H16 -> 3 | K16: 114 | L16: =ROUND(J16*$L$3,2) -> 12.46 | M16: =N16-K16 -> 4 | N16: 118 | O16: =ROUND(M16*$O$3,2) -> 25.54 | P16: =Q16-N16 -> 4 | Q16: 122 | R16: =ROUND(P16*$R$3,2) -> 11.48 | S16: =+T16-Q16 -> 5 | T16: 127 | U16: =ROUND(S16*$U$3,2) -> 14.9 | V16: =+W16-T16 -> 6 | W16: 133 | X16: =V16*$X$3 -> 17.8512 | Y16: =+Z16-W16 -> 7 | Z16: 140 | AA16: =ROUND(Y16*$AA$3,2) -> 21.69
A17: DEPA-203 | B17: 234 | C17: =D17-B17 -> 4 | D17: 238 | E17: =F17-D17 -> 4 | F17: 242 | G17: =H17-F17 -> 8 | H17: 250 | I17: =ROUND(G17*$I$3,2) -> 29.87 | J17: =K17-H17 -> 3 | K17: 253 | L17: =ROUND(J17*$L$3,2) -> 12.46 | M17: =N17-K17 -> 4 | N17: 257 | O17: =ROUND(M17*$O$3,2) -> 25.54 | P17: =Q17-N17 -> 8 | Q17: 265 | R17: =ROUND(P17*$R$3,2) -> 22.96 | S17: =+T17-Q17 -> 55 | T17: 320 | U17: =ROUND(S17*$U$3,2) -> 163.89 | V17: =+W17-T17 -> 29 | W17: 349 | X17: =V17*$X$3 -> 86.2808 | Y17: =+Z17-W17 -> 34 | Z17: 383 | AA17: =ROUND(Y17*$AA$3,2) -> 105.36 | AC17: *pablo
A18: DEPA-204 | B18: 145 | C18: =D18-B18 -> 4 | D18: 149 | E18: =F18-D18 -> 5 | F18: 154 | G18: =H18-F18 -> 7 | H18: 161 | I18: =ROUND(G18*$I$3,2) -> 26.14 | J18: =K18-H18 -> 5 | K18: 166 | L18: =ROUND(J18*$L$3,2) -> 20.77 | M18: =N18-K18 -> 4 | N18: 170 | O18: =ROUND(M18*$O$3,2) -> 25.54 | P18: =Q18-N18 -> 4 | Q18: 174 | R18: =ROUND(P18*$R$3,2) -> 11.48 | S18: =+T18-Q18 -> 6 | T18: 180 | U18: =ROUND(S18*$U$3,2) -> 17.88 | V18: =+W18-T18 -> 5 | W18: 185 | X18: =V18*$X$3 -> 14.876 | Y18: =+Z18-W18 -> 7 | Z18: 192 | AA18: =ROUND(Y18*$AA$3,2) -> 21.69
A19: DEPA-205 | B19: 157 | C19: =D19-B19 -> 8 | D19: 165 | E19: =F19-D19 -> 7 | F19: 172 | G19: =H19-F19 -> 7 | H19: 179 | I19: =ROUND(G19*$I$3,2) -> 26.14 | J19: =K19-H19 -> 7 | K19: 186 | L19: =ROUND(J19*$L$3,2) -> 29.08 | M19: =N19-K19 -> 5 | N19: 191 | O19: =ROUND(M19*$O$3,2) -> 31.93 | P19: =Q19-N19 -> 3 | Q19: 194 | R19: =ROUND(P19*$R$3,2) -> 8.61 | S19: =+T19-Q19 -> 8 | T19: 202 | U19: =ROUND(S19*$U$3,2) -> 23.84 | V19: =+W19-T19 -> 9 | W19: 211 | X19: =V19*$X$3 -> 26.7768 | Y19: =+Z19-W19 -> 10 | Z19: 221 | AA19: =ROUND(Y19*$AA$3,2) -> 30.99
A20: DEPA-206 | B20: 131 | C20: =D20-B20 -> 4 | D20: 135 | E20: =F20-D20 -> 4 | F20: 139 | G20: =H20-F20 -> 7 | H20: 146 | I20: =ROUND(G20*$I$3,2) -> 26.14 | J20: =K20-H20 -> 5 | K20: 151 | L20: =ROUND(J20*$L$3,2) -> 20.77 | M20: =N20-K20 -> 3 | N20: 154 | O20: =ROUND(M20*$O$3,2) -> 19.16 | P20: =Q20-N20 -> 2 | Q20: 156 | R20: =ROUND(P20*$R$3,2) -> 5.74 | S20: =+T20-Q20 -> 0 | T20: 156 | U20: =ROUND(S20*$U$3,2) -> 0 | V20: =+W20-T20 -> 1 | W20: 157 | X20: =V20*$X$3 -> 2.9752 | Y20: =+Z20-W20 -> 1 | Z20: 158 | AA20: =ROUND(Y20*$AA$3,2) -> 3.1
A21: DEPA-207 | B21: 196 | C21: =D21-B21 -> 4 | D21: 200 | E21: =F21-D21 -> 4 | F21: 204 | G21: =H21-F21 -> 5 | H21: 209 | I21: =ROUND(G21*$I$3,2) -> 18.67 | J21: =K21-H21 -> 4 | K21: 213 | L21: =ROUND(J21*$L$3,2) -> 16.62 | M21: =N21-K21 -> 3 | N21: 216 | O21: =ROUND(M21*$O$3,2) -> 19.16 | P21: =Q21-N21 -> 5 | Q21: 221 | R21: =ROUND(P21*$R$3,2) -> 14.35 | S21: =+T21-Q21 -> 0 | T21: 221 | U21: =ROUND(S21*$U$3,2) -> 0 | V21: =+W21-T21 -> 7 | W21: 228 | X21: =V21*$X$3 -> 20.8264 | Y21: =+Z21-W21 -> 9 | Z21: 237 | AA21: =ROUND(Y21*$AA$3,2) -> 27.89
A22: DEPA-208 | B22: 258 | C22: =D22-B22 -> 9 | D22: 267 | E22: =F22-D22 -> 9 | F22: 276 | G22: =H22-F22 -> 5 | H22: 281 | I22: =ROUND(G22*$I$3,2) -> 18.67 | J22: =K22-H22 -> 12 | K22: 293 | L22: =ROUND(J22*$L$3,2) -> 49.86 | M22: =N22-K22 -> 5 | N22: 298 | O22: =ROUND(M22*$O$3,2) -> 31.93 | P22: =Q22-N22 -> 8 | Q22: 306 | R22: =ROUND(P22*$R$3,2) -> 22.96 | S22: =+T22-Q22 -> 10 | T22: 316 | U22: =ROUND(S22*$U$3,2) -> 29.8 | V22: =+W22-T22 -> 9 | W22: 325 | X22: =V22*$X$3 -> 26.7768 | Y22: =+Z22-W22 -> 13 | Z22: 338 | AA22: =ROUND(Y22*$AA$3,2) -> 40.29
A23: DEPA-209 | B23: 14 | C23: =D23-B23 -> 1 | D23: 15 | E23: =F23-D23 -> 1 | F23: 16 | G23: =H23-F23 -> 0 | H23: 16 | I23: =ROUND(G23*$I$3,2) -> 0 | J23: =K23-H23 -> 1 | K23: 17 | L23: =ROUND(J23*$L$3,2) -> 4.15 | M23: =N23-K23 -> 0 | N23: 17 | O23: =ROUND(M23*$O$3,2) -> 0 | P23: =Q23-N23 -> 1 | Q23: 18 | R23: =ROUND(P23*$R$3,2) -> 2.87 | S23: =+T23-Q23 -> 1 | T23: 19 | U23: =ROUND(S23*$U$3,2) -> 2.98 | V23: =+W23-T23 -> 0 | W23: 19 | X23: =V23*$X$3 -> 0 | Y23: =+Z23-W23 -> 1 | Z23: 20 | AA23: =ROUND(Y23*$AA$3,2) -> 3.1
A24: DEPA-210 | B24: 332.49 | C24: =D24-B24 -> 16.86 | D24: 349.35 | E24: =F24-D24 -> 18.18 | F24: 367.53 | G24: =H24-F24 -> 15.545 | H24: 383.075 | I24: =ROUND(G24*$I$3,2) -> 58.05 | J24: =K24-H24 -> 16.925 | K24: 400 | L24: =ROUND(J24*$L$3,2) -> 70.32 | M24: =N24-K24 -> 13.082 | N24: 413.082 | O24: =ROUND(M24*$O$3,2) -> 83.54 | P24: =Q24-N24 -> 14.926 | Q24: 428.008 | R24: =ROUND(P24*$R$3,2) -> 42.84 | S24: =+T24-Q24 -> 3.567 | T24: 431.575 | U24: =ROUND(S24*$U$3,2) -> 10.63 | V24: =+W24-T24 -> 8.425 | W24: 440 | X24: =V24*$X$3 -> 25.06606 | Y24: =+Z24-W24 -> 12 | Z24: 452 | AA24: =ROUND(Y24*$AA$3,2) -> 37.19
A25: DEPA-301 | B25: 72 | C25: =D25-B25 -> 1 | D25: 73 | E25: =F25-D25 -> 1 | F25: 74 | G25: =H25-F25 -> 2 | H25: 76 | I25: =ROUND(G25*$I$3,2) -> 7.47 | J25: =K25-H25 -> 1 | K25: 77 | L25: =ROUND(J25*$L$3,2) -> 4.15 | M25: =N25-K25 -> 0 | N25: 77 | O25: =ROUND(M25*$O$3,2) -> 0 | P25: =Q25-N25 -> 1 | Q25: 78 | R25: =ROUND(P25*$R$3,2) -> 2.87 | S25: =+T25-Q25 -> 0 | T25: 78 | U25: =ROUND(S25*$U$3,2) -> 0 | V25: =+W25-T25 -> 0 | W25: 78 | X25: =V25*$X$3 -> 0 | Y25: =+Z25-W25 -> 1 | Z25: 79 | AA25: =ROUND(Y25*$AA$3,2) -> 3.1
A26: DEPA-302 | B26: 12 | C26: =D26-B26 -> 6 | D26: 18 | E26: =F26-D26 -> 4 | F26: 22 | G26: =H26-F26 -> 5 | H26: 27 | I26: =ROUND(G26*$I$3,2) -> 18.67 | J26: =K26-H26 -> 5 | K26: 32 | L26: =ROUND(J26*$L$3,2) -> 20.77 | M26: =N26-K26 -> 5 | N26: 37 | O26: =ROUND(M26*$O$3,2) -> 31.93 | P26: =Q26-N26 -> 9 | Q26: 46 | R26: =ROUND(P26*$R$3,2) -> 25.83 | S26: =+T26-Q26 -> 12 | T26: 58 | U26: =ROUND(S26*$U$3,2) -> 35.76 | V26: =+W26-T26 -> 11 | W26: 69 | X26: =V26*$X$3 -> 32.7272 | Y26: =+Z26-W26 -> 11 | Z26: 80 | AA26: =ROUND(Y26*$AA$3,2) -> 34.09
A27: DEPA-303 | B27: 58 | C27: =D27-B27 -> 0 | D27: 58 | E27: =F27-D27 -> 0 | F27: 58 | G27: =H27-F27 -> 3 | H27: 61 | I27: =ROUND(G27*$I$3,2) -> 11.2 | J27: =K27-H27 -> 0 | K27: 61 | L27: =ROUND(J27*$L$3,2) -> 0 | M27: =N27-K27 -> 0 | N27: 61 | O27: =ROUND(M27*$O$3,2) -> 0 | P27: =Q27-N27 -> 1 | Q27: 62 | R27: =ROUND(P27*$R$3,2) -> 2.87 | S27: =+T27-Q27 -> 0 | T27: 62 | U27: =ROUND(S27*$U$3,2) -> 0 | V27: =+W27-T27 -> 1 | W27: 63 | X27: =V27*$X$3 -> 2.9752 | Y27: =+Z27-W27 -> 1 | Z27: 64 | AA27: =ROUND(Y27*$AA$3,2) -> 3.1
A28: DEPA-304 | B28: 434 | C28: =D28-B28 -> 13 | D28: 447 | E28: =F28-D28 -> 13 | F28: 460 | G28: =H28-F28 -> 13 | H28: 473 | I28: =ROUND(G28*$I$3,2) -> 48.54 | J28: =K28-H28 -> 12 | K28: 485 | L28: =ROUND(J28*$L$3,2) -> 49.86 | M28: =N28-K28 -> 7 | N28: 492 | O28: =ROUND(M28*$O$3,2) -> 44.7 | P28: =Q28-N28 -> 6 | Q28: 498 | R28: =ROUND(P28*$R$3,2) -> 17.22 | S28: =+T28-Q28 -> 2 | T28: 500 | U28: =ROUND(S28*$U$3,2) -> 5.96 | V28: =+W28-T28 -> 4 | W28: 504 | X28: =V28*$X$3 -> 11.9008 | Y28: =+Z28-W28 -> 9 | Z28: 513 | AA28: =ROUND(Y28*$AA$3,2) -> 27.89
A29: DEPA-305 | B29: 60.11 | C29: =D29-B29 -> 4.28 | D29: 64.39 | E29: =F29-D29 -> 4.77 | F29: 69.16 | G29: =H29-F29 -> 5.735 | H29: 74.895 | I29: =ROUND(G29*$I$3,2) -> 21.42 | J29: =K29-H29 -> 2.581 | K29: 77.476 | L29: =ROUND(J29*$L$3,2) -> 10.72 | M29: =N29-K29 -> 2.935 | N29: 80.411 | O29: =ROUND(M29*$O$3,2) -> 18.74 | P29: =Q29-N29 -> 4.589 | Q29: 85 | R29: =ROUND(P29*$R$3,2) -> 13.17 | S29: =+T29-Q29 -> 5.048 | T29: 90.048 | U29: =ROUND(S29*$U$3,2) -> 15.04 | V29: =+W29-T29 -> 5.952 | W29: 96 | X29: =V29*$X$3 -> 17.70839 | Y29: =+Z29-W29 -> 7 | Z29: 103 | AA29: =ROUND(Y29*$AA$3,2) -> 21.69
... A122: DEPA-1103 | B122: 210 | C122: =D122-B122 -> 4 | D122: 214 | E122: =F122-D122 -> 4 | F122: 218 | G122: =H122-F122 -> 9 | H122: 227 | I122: =ROUND(G122*$I$3,2) -> 33.61 | J122: =K122-H122 -> 3 | K122: 230 | L122: =ROUND(J122*$L$3,2) -> 12.46 | M122: =N122-K122 -> 2 | N122: 232 | O122: =ROUND(M122*$O$3,2) -> 12.77 | P122: =Q122-N122 -> 4 | Q122: 236 | R122: =ROUND(P122*$R$3,2) -> 11.48 | S122: =+T122-Q122 -> 5 | T122: 241 | U122: =ROUND(S122*$U$3,2) -> 14.9 | V122: =+W122-T122 -> 10 | W122: 251 | X122: =V122*$X$3 -> 29.752 | Y122: =+Z122-W122 -> 7 | Z122: 258 | AA122: =ROUND(Y122*$AA$3,2) -> 21.69
A123: DEPA-1104 | B123: 298 | C123: =D123-B123 -> 5 | D123: 303 | E123: =F123-D123 -> 4 | F123: 307 | G123: 5 | H123: 62 | I123: =ROUND(G123*$I$3,2) -> 18.67 | J123: =K123-H123 -> 13 | K123: 75 | L123: =ROUND(J123*$L$3,2) -> 54.01 | M123: =N123-K123 -> 9 | N123: 84 | O123: =ROUND(M123*$O$3,2) -> 57.47 | P123: =Q123-N123 -> 11 | Q123: 95 | R123: =ROUND(P123*$R$3,2) -> 31.57 | S123: =+T123-Q123 -> 12 | T123: 107 | U123: =ROUND(S123*$U$3,2) -> 35.76 | V123: =+W123-T123 -> 12 | W123: 119 | X123: =V123*$X$3 -> 35.7024 | Y123: =+Z123-W123 -> 3 | Z123: 122 | AA123: =ROUND(Y123*$AA$3,2) -> 9.3 | AD123: *medidor nuevo val. 25/08/2025
A124: DEPA-1105 | B124: 380.08 | C124: =D124-B124 -> 10.82 | D124: 390.9 | E124: =F124-D124 -> 9.63 | F124: 400.53 | G124: =H124-F124 -> 11.706 | H124: 412.236 | I124: =ROUND(G124*$I$3,2) -> 43.71 | J124: =K124-H124 -> 12.277 | K124: 424.513 | L124: =ROUND(J124*$L$3,2) -> 51.01 | M124: =N124-K124 -> 8.038 | N124: 432.551 | O124: =ROUND(M124*$O$3,2) -> 51.33 | P124: =Q124-N124 -> 7.449 | Q124: 440 | R124: =ROUND(P124*$R$3,2) -> 21.38 | S124: =+T124-Q124 -> 12.669 | T124: 452.669 | U124: =ROUND(S124*$U$3,2) -> 37.75 | V124: =+W124-T124 -> 9.331 | W124: 462 | X124: =V124*$X$3 -> 27.761591 | Y124: =+Z124-W124 -> 10 | Z124: 472 | AA124: =ROUND(Y124*$AA$3,2) -> 30.99
A125: DEPA-1106 | B125: 35 | C125: =D125-B125 -> 1 | D125: 36 | E125: =F125-D125 -> 0 | F125: 36 | G125: =H125-F125 -> 1 | H125: 37 | I125: =ROUND(G125*$I$3,2) -> 3.73 | J125: =K125-H125 -> 0 | K125: 37 | L125: =ROUND(J125*$L$3,2) -> 0 | M125: =N125-K125 -> 0 | N125: 37 | O125: =ROUND(M125*$O$3,2) -> 0 | P125: =Q125-N125 -> 1 | Q125: 38 | R125: =ROUND(P125*$R$3,2) -> 2.87 | S125: =+T125-Q125 -> 0 | T125: 38 | U125: =ROUND(S125*$U$3,2) -> 0 | V125: =+W125-T125 -> 0 | W125: 38 | X125: =V125*$X$3 -> 0 | Y125: =+Z125-W125 -> 1 | Z125: 39 | AA125: =ROUND(Y125*$AA$3,2) -> 3.1
A126: DEPA-1107 | B126: 288 | C126: =D126-B126 -> 5 | D126: 293 | E126: =F126-D126 -> 9 | F126: 302 | G126: =H126-F126 -> 8 | H126: 310 | I126: =ROUND(G126*$I$3,2) -> 29.87 | J126: =K126-H126 -> 8 | K126: 318 | L126: =ROUND(J126*$L$3,2) -> 33.24 | M126: =N126-K126 -> 3 | N126: 321 | O126: =ROUND(M126*$O$3,2) -> 19.16 | P126: =Q126-N126 -> 5 | Q126: 326 | R126: =ROUND(P126*$R$3,2) -> 14.35 | S126: =+T126-Q126 -> 9 | T126: 335 | U126: =ROUND(S126*$U$3,2) -> 26.82 | V126: =+W126-T126 -> 8 | W126: 343 | X126: =V126*$X$3 -> 23.8016 | Y126: =+Z126-W126 -> 11 | Z126: 354 | AA126: =ROUND(Y126*$AA$3,2) -> 34.09
A127: DEPA-1108 | B127: 137 | C127: =D127-B127 -> 2 | D127: 139 | E127: =F127-D127 -> 3 | F127: 142 | G127: =H127-F127 -> 5 | H127: 147 | I127: =ROUND(G127*$I$3,2) -> 18.67 | J127: =K127-H127 -> 2 | K127: 149 | L127: =ROUND(J127*$L$3,2) -> 8.31 | M127: =N127-K127 -> 2 | N127: 151 | O127: =ROUND(M127*$O$3,2) -> 12.77 | P127: =Q127-N127 -> 3 | Q127: 154 | R127: =ROUND(P127*$R$3,2) -> 8.61 | S127: =+T127-Q127 -> 3 | T127: 157 | U127: =ROUND(S127*$U$3,2) -> 8.94 | V127: =+W127-T127 -> 3 | W127: 160 | X127: =V127*$X$3 -> 8.9256 | Y127: =+Z127-W127 -> 6 | Z127: 166 | AA127: =ROUND(Y127*$AA$3,2) -> 18.59
A128: DEPA-1109 | B128: 199 | C128: =D128-B128 -> 4 | D128: 203 | E128: =F128-D128 -> 3 | F128: 206 | G128: =H128-F128 -> 5 | H128: 211 | I128: =ROUND(G128*$I$3,2) -> 18.67 | J128: =K128-H128 -> 4 | K128: 215 | L128: =ROUND(J128*$L$3,2) -> 16.62 | M128: =N128-K128 -> 3 | N128: 218 | O128: =ROUND(M128*$O$3,2) -> 19.16 | P128: =Q128-N128 -> 3 | Q128: 221 | R128: =ROUND(P128*$R$3,2) -> 8.61 | S128: =+T128-Q128 -> 4 | T128: 225 | U128: =ROUND(S128*$U$3,2) -> 11.92 | V128: =+W128-T128 -> 2 | W128: 227 | X128: =V128*$X$3 -> 5.9504 | Y128: =+Z128-W128 -> 3 | Z128: 230 | AA128: =ROUND(Y128*$AA$3,2) -> 9.3
A129: DEPA-1110 | B129: 278.12 | C129: =D129-B129 -> 5.13 | D129: 283.25 | E129: =F129-D129 -> 6.05 | F129: 289.3 | G129: =H129-F129 -> 7.15 | H129: 296.45 | I129: =ROUND(G129*$I$3,2) -> 26.7 | J129: =K129-H129 -> 5.854 | K129: 302.304 | L129: =ROUND(J129*$L$3,2) -> 24.32 | M129: =N129-K129 -> 4.304 | N129: 306.608 | O129: =ROUND(M129*$O$3,2) -> 27.48 | P129: =Q129-N129 -> 4.392 | Q129: 311 | R129: =ROUND(P129*$R$3,2) -> 12.61 | S129: =+T129-Q129 -> 7.308 | T129: 318.308 | U129: =ROUND(S129*$U$3,2) -> 21.78 | V129: =+W129-T129 -> 4.692 | W129: 323 | X129: =V129*$X$3 -> 13.959638 | Y129: =+Z129-W129 -> 8 | Z129: 331 | AA129: =ROUND(Y129*$AA$3,2) -> 24.79
A130: DEPA-1111 | B130: 141.87 | C130: =D130-B130 -> 7 | D130: 148.87 | E130: =F130-D130 -> 6.35 | F130: 155.22 | G130: =H130-F130 -> 6.582 | H130: 161.802 | I130: =ROUND(G130*$I$3,2) -> 24.58 | J130: =K130-H130 -> 6.058 | K130: 167.86 | L130: =ROUND(J130*$L$3,2) -> 25.17 | M130: =N130-K130 -> 4.032 | N130: 171.892 | O130: =ROUND(M130*$O$3,2) -> 25.75 | P130: =Q130-N130 -> 5.108 | Q130: 177 | R130: =ROUND(P130*$R$3,2) -> 14.66 | S130: =+T130-Q130 -> 6.588 | T130: 183.588 | U130: =ROUND(S130*$U$3,2) -> 19.63 | V130: =+W130-T130 -> 6.412 | W130: 190 | X130: =V130*$X$3 -> 19.076982 | Y130: =+Z130-W130 -> 8 | Z130: 198 | AA130: =ROUND(Y130*$AA$3,2) -> 24.79
A131: DEPA-1112 | B131: 239 | C131: =D131-B131 -> 18 | D131: 257 | E131: =F131-D131 -> 7 | F131: 264 | G131: =H131-F131 -> 13 | H131: 277 | I131: =ROUND(G131*$I$3,2) -> 48.54 | J131: =K131-H131 -> 9 | K131: 286 | L131: =ROUND(J131*$L$3,2) -> 37.39 | M131: =N131-K131 -> 7 | N131: 293 | O131: =ROUND(M131*$O$3,2) -> 44.7 | P131: =Q131-N131 -> 8 | Q131: 301 | R131: =ROUND(P131*$R$3,2) -> 22.96 | S131: =+T131-Q131 -> 10 | T131: 311 | U131: =ROUND(S131*$U$3,2) -> 29.8 | V131: =+W131-T131 -> 8 | W131: 319 | X131: =V131*$X$3 -> 23.8016 | Y131: =+Z131-W131 -> 9 | Z131: 328 | AA131: =ROUND(Y131*$AA$3,2) -> 27.89
A132: DEPA-1201 | B132: 617 | C132: =D132-B132 -> 12 | D132: 629 | E132: =F132-D132 -> 20 | F132: 649 | G132: =H132-F132 -> 22 | H132: =496+175 -> 671 | I132: =ROUND(G132*$I$3,2) -> 82.15 | J132: =K132-H132 -> 20 | K132: =511+180 -> 691 | L132: =ROUND(J132*$L$3,2) -> 83.09 | M132: =N132-K132 -> 15 | N132: =522+184 -> 706 | O132: =ROUND(M132*$O$3,2) -> 95.78 | P132: =Q132-N132 -> 17 | Q132: =535+188 -> 723 | R132: =ROUND(P132*$R$3,2) -> 48.8 | S132: =+T132-Q132 -> 22 | T132: =552+193 -> 745 | U132: =ROUND(S132*$U$3,2) -> 65.56 | V132: =+W132-T132 -> 21 | W132: =567+199 -> 766 | X132: =V132*$X$3 -> 62.4792 | Y132: =+Z132-W132 -> 22 | Z132: =583+205 -> 788 | AA132: =ROUND(Y132*$AA$3,2) -> 68.18
A133: DEPA-1204 | B133: 113 | C133: =D133-B133 -> 7 | D133: 120 | E133: =F133-D133 -> 6 | F133: 126 | G133: =H133-F133 -> 7 | H133: 133 | I133: =ROUND(G133*$I$3,2) -> 26.14 | J133: =K133-H133 -> 6 | K133: 139 | L133: =ROUND(J133*$L$3,2) -> 24.93 | M133: =N133-K133 -> 5 | N133: 144 | O133: =ROUND(M133*$O$3,2) -> 31.93 | P133: =Q133-N133 -> 6 | Q133: 150 | R133: =ROUND(P133*$R$3,2) -> 17.22 | S133: =+T133-Q133 -> 9 | T133: 159 | U133: =ROUND(S133*$U$3,2) -> 26.82 | V133: =+W133-T133 -> 8 | W133: 167 | X133: =V133*$X$3 -> 23.8016 | Y133: =+Z133-W133 -> 4 | Z133: 171 | AA133: =ROUND(Y133*$AA$3,2) -> 12.4
...

Sheet calculo
A1: CODIGO | B1: PROPIETARIO(S) | C1: PREDIO | D1: ÁREA TECHADA | E1: ÁREA OCUPADA | F1: % PARTICIPACIÓN | G1: VALOR CUOTA | H1: AGUA CONSUMO | I1: SUMA
A2: PP-000 | B2: SIN IDENTIFICAR | C2: PP-LAV | F2: 0.004415 | G2: =ROUND(pres!$C$2*calculo!F2,2) -> 265.41 | H2: =IFERROR(VLOOKUP(C2,consumo_agua!$A$7:$AA$202,27,0),0) -> 213.82 | I2: =SUM(G2:H2) -> 479.23
A3: PP-001 | B3: AJK ASOCIADOS SAC | C3: DEPA-1605 | D3: 78.95 | E3: 78.95 | F3: 0.0044974 | G3: =ROUND(pres!$C$2*calculo!F3,2) -> 270.37 | H3: =IFERROR(VLOOKUP(C3,consumo_agua!$A$7:$AA$202,27,0),0) -> 15.49 | I3: =SUM(G3:H3) -> 285.86
A4: PP-001 | B4: AJK ASOCIADOS SAC | C4: ESTA-020 | D4: 0 | E4: 0 | F4: 0.001269 | G4: =ROUND(pres!$C$2*calculo!F4,2) -> 76.29 | H4: =IFERROR(VLOOKUP(C4,consumo_agua!$A$7:$AA$202,27,0),0) -> 0 | I4: =SUM(G4:H4) -> 76.29
A5: PP-002 | B5: ALBAN MALACHE CHABELI | C5: DEPA-612 | D5: 74.6 | E5: 74.6 | F5: 0.0044974 | G5: =ROUND(pres!$C$2*calculo!F5,2) -> 270.37 | H5: =IFERROR(VLOOKUP(C5,consumo_agua!$A$7:$AA$202,27,0),0) -> 24.79 | I5: =SUM(G5:H5) -> 295.16
A6: PP-002 | B6: ALBAN MALACHE CHABELI | C6: ESTA-067 | D6: 0 | E6: 0 | F6: 0.001269 | G6: =ROUND(pres!$C$2*calculo!F6,2) -> 76.29 | H6: =IFERROR(VLOOKUP(C6,consumo_agua!$A$7:$AA$202,27,0),0) -> 0 | I6: =SUM(G6:H6) -> 76.29
A7: PP-003 | B7: RUIZ JAVIER ALEJANDRO | C7: DEPA-811 | D7: 33 | E7: 33 | F7: 0.0026939 | G7: =ROUND(pres!$C$2*calculo!F7,2) -> 161.95 | H7: =IFERROR(VLOOKUP(C7,consumo_agua!$A$7:$AA$202,27,0),0) -> 9.3 | I7: =SUM(G7:H7) -> 171.25
A8: PP-004 | B8: ALEXANDER STRAHLE JURGEN | C8: DEPA-902 | D8: 77.05 | E8: 77.05 | F8: 0.0044974 | G8: =ROUND(pres!$C$2*calculo!F8,2) -> 270.37 | H8: =IFERROR(VLOOKUP(C8,consumo_agua!$A$7:$AA$202,27,0),0) -> 12.4 | I8: =SUM(G8:H8) -> 282.77
A9: PP-004 | B9: ALEXANDER STRAHLE JURGEN | C9: ESTA-042 | D9: 0 | E9: 0 | F9: 0.001269 | G9: =ROUND(pres!$C$2*calculo!F9,2) -> 76.29 | H9: =IFERROR(VLOOKUP(C9,consumo_agua!$A$7:$AA$202,27,0),0) -> 0 | I9: =SUM(G9:H9) -> 76.29
A10: PP-005 | B10: ALVA CUELLAR DUGLAS CONCEPCION | C10: DEPA-1205 | D10: 78.95 | E10: 78.95 | F10: 0.0044974 | G10: =ROUND(pres!$C$2*calculo!F10,2) -> 270.37 | H10: =IFERROR(VLOOKUP(C10,consumo_agua!$A$7:$AA$202,27,0),0) -> 55.78 | I10: =SUM(G10:H10) -> 326.15
A11: PP-005 | B11: ALVA CUELLAR DUGLAS CONCEPCION | C11: ESTA-077 | D11: 0 | E11: 0 | F11: 0.001269 | G11: =ROUND(pres!$C$2*calculo!F11,2) -> 76.29 | H11: =IFERROR(VLOOKUP(C11,consumo_agua!$A$7:$AA$202,27,0),0) -> 0 | I11: =SUM(G11:H11) -> 76.29
A12: PP-006 | B12: ALVARADO BRINGAS MILUSKA CARLA | C12: DEPA-1001 | D12: 92.5 | E12: 92.5 | F12: 0.0056773 | G12: =ROUND(pres!$C$2*calculo!F12,2) -> 341.3 | H12: =IFERROR(VLOOKUP(C12,consumo_agua!$A$7:$AA$202,27,0),0) -> 3.1 | I12: =SUM(G12:H12) -> 344.4
A13: PP-006 | B13: ALVARADO BRINGAS MILUSKA CARLA | C13: ESTA-063 | D13: 0 | E13: 0 | F13: 0.001269 | G13: =ROUND(pres!$C$2*calculo!F13,2) -> 76.29 | H13: =IFERROR(VLOOKUP(C13,consumo_agua!$A$7:$AA$202,27,0),0) -> 0 | I13: =SUM(G13:H13) -> 76.29
A14: PP-007 | B14: ANTON ENICE | C14: DEPA-610 | D14: 81 | E14: 81 | F14: 0.0044974 | G14: =ROUND(pres!$C$2*calculo!F14,2) -> 270.37 | H14: =IFERROR(VLOOKUP(C14,consumo_agua!$A$7:$AA$202,27,0),0) -> 15.49 | I14: =SUM(G14:H14) -> 285.86
... A163: PP-083 | B163: INDUSTRIAS GENERALES SAC | C163: ESTA-083 | D163: 0 | E163: 0 | F163: 0.001269 | G163: =ROUND(pres!$C$2*calculo!F163,2) -> 76.29 | H163: =IFERROR(VLOOKUP(C163,consumo_agua!$A$7:$AA$202,27,0),0) -> 0 | I163: =SUM(G163:H163) -> 76.29
A164: PP-084 | B164: INFANTES JHEYSON | G164: =ROUND(pres!$C$2*calculo!F164,2) -> 0 | H164: =IFERROR(VLOOKUP(C164,consumo_agua!$A$7:$AA$202,27,0),0) -> 0 | I164: =SUM(G164:H164) -> 0
A165: PP-084 | B165: INFANTES JHEYSON | C165: ESTA-133 | D165: 0 | E165: 0 | F165: 0.001269 | G165: =ROUND(pres!$C$2*calculo!F165,2) -> 76.29 | H165: =IFERROR(VLOOKUP(C165,consumo_agua!$A$7:$AA$202,27,0),0) -> 0 | I165: =SUM(G165:H165) -> 76.29
A166: PP-085 | B166: PARI NUÑEZ LEONOR | C166: DEPA-512 | D166: 74.6 | E166: 74.6 | F166: 0.0044974 | G166: =ROUND(pres!$C$2*calculo!F166,2) -> 270.37 | H166: =IFERROR(VLOOKUP(C166,consumo_agua!$A$7:$AA$202,27,0),0) -> 58.88 | I166: =SUM(G166:H166) -> 329.25
A167: PP-085 | B167: PARI NUÑEZ LEONOR | C167: ESTA-146 | D167: 0 | E167: 0 | F167: 0.001269 | G167: =ROUND(pres!$C$2*calculo!F167,2) -> 76.29 | H167: =IFERROR(VLOOKUP(C167,consumo_agua!$A$7:$AA$202,27,0),0) -> 0 | I167: =SUM(G167:H167) -> 76.29
A168: PP-086 | B168: IZQUIERDO ALATA LIAM JUAN PEDRO | C168: DEPA-710 | D168: 81 | E168: 81 | F168: 0.0044974 | G168: =ROUND(pres!$C$2*calculo!F168,2) -> 270.37 | H168: =IFERROR(VLOOKUP(C168,consumo_agua!$A$7:$AA$202,27,0),0) -> 24.79 | I168: =SUM(G168:H168) -> 295.16
A169: PP-086 | B169: IZQUIERDO ALATA LIAM JUAN PEDRO | C169: ESTA-117 | D169: 0 | E169: 0 | F169: 0.001269 | G169: =ROUND(pres!$C$2*calculo!F169,2) -> 76.29 | H169: =IFERROR(VLOOKUP(C169,consumo_agua!$A$7:$AA$202,27,0),0) -> 0 | I169: =SUM(G169:H169) -> 76.29
A170: PP-087 | B170: JARA CISNEROS RICHARD | C170: DEPA-1604 | D170: 76.15 | E170: 76.15 | F170: 0.0044974 | G170: =ROUND(pres!$C$2*calculo!F170,2) -> 270.37 | H170: =IFERROR(VLOOKUP(C170,consumo_agua!$A$7:$AA$202,27,0),0) -> 9.3 | I170: =SUM(G170:H170) -> 279.67
A171: PP-087 | B171: JARA CISNEROS RICHARD | C171: ESTA-129 | D171: 0 | E171: 0 | F171: 0.001269 | G171: =ROUND(pres!$C$2*calculo!F171,2) -> 76.29 | H171: =IFERROR(VLOOKUP(C171,consumo_agua!$A$7:$AA$202,27,0),0) -> 0 | I171: =SUM(G171:H171) -> 76.29
A172: PP-088 | B172: JIMENEZ CARMEN | C172: DEPA-508 | D172: 33.2 | E172: 33.2 | F172: 0.0026939 | G172: =ROUND(pres!$C$2*calculo!F172,2) -> 161.95 | H172: =IFERROR(VLOOKUP(C172,consumo_agua!$A$7:$AA$202,27,0),0) -> 0 | I172: =SUM(G172:H172) -> 161.95
A173: PP-088 | B173: JIMENEZ CARMEN | C173: DEPO-171 | D173: 0 | E173: 0 | F173: 0.0003675 | G173: =ROUND(pres!$C$2*calculo!F173,2) -> 22.09 | H173: =IFERROR(VLOOKUP(C173,consumo_agua!$A$7:$AA$202,27,0),0) -> 0 | I173: =SUM(G173:H173) -> 22.09
A174: PP-089 | B174: JO RENZO | C174: DEPA-1212 | D174: 74.6 | E174: 74.6 | F174: 0.0044974 | G174: =ROUND(pres!$C$2*calculo!F174,2) -> 270.37 | H174: =IFERROR(VLOOKUP(C174,consumo_agua!$A$7:$AA$202,27,0),0) -> 49.58 | I174: =SUM(G174:H174) -> 319.95
A175: PP-089 | B175: JO RENZO | C175: ESTA-085 | D175: 0 | E175: 0 | F175: 0.001269 | G175: =ROUND(pres!$C$2*calculo!F175,2) -> 76.29 | H175: =IFERROR(VLOOKUP(C175,consumo_agua!$A$7:$AA$202,27,0),0) -> 0 | I175: =SUM(G175:H175) -> 76.29
A176: PP-090 | B176: JURADO PAZ Y MIÑO VICTOR | C176: DEPA-703 | D176: 68 | E176: 68 | F176: 0.0044974 | G176: =ROUND(pres!$C$2*calculo!F176,2) -> 270.37 | H176: =IFERROR(VLOOKUP(C176,consumo_agua!$A$7:$AA$202,27,0),0) -> 0 | I176: =SUM(G176:H176) -> 270.37
... A382: PP-202 | B382: PALOMINO CRISTIAN | C382: ESTA-133 | D382: 0 | E382: 0 | F382: 0.001269 | G382: =ROUND(pres!$C$2*calculo!F382,2) -> 76.29 | H382: =IFERROR(VLOOKUP(C382,consumo_agua!$A$7:$AA$202,27,0),0) -> 0 | I382: =SUM(G382:H382) -> 76.29
A383: PP-LAV | B383: LAVANDERIA PRONTOMATIK | C383: PRONTOMATIK
D384: =SUM(D1:D383) -> 12767.37 | E384: =SUM(E1:E383) -> 12887.95 | F384: =SUM(F2:F383) -> 0.9999843 | G384: =SUM(G2:G383) -> 60116.18 | H384: =SUM(H1:H383) -> 4708.33 | I384: =SUM(I1:I383) -> 64824.51

Sheet cuota_resumen
C3: Valores
A4: CODIGO | B4: PROPIETARIO(S) | C4: PREDIOS | D4: VALOR CUOTA | E4: AGUA CONSUMO | F4: SUMA
A5: PP-001 | B5: AJK ASOCIADOS SAC | C5: 2 | D5: 346.66 | E5: 15.49 | F5: 362.15
A6: PP-002 | B6: ALBAN MALACHE CHABELI | C6: 2 | D6: 346.66 | E6: 24.79 | F6: 371.45
A7: PP-003 | B7: RUIZ JAVIER ALEJANDRO | C7: 1 | D7: 161.95 | E7: 9.3 | F7: 171.25
A8: PP-004 | B8: ALEXANDER STRAHLE JURGEN | C8: 2 | D8: 346.66 | E8: 12.4 | F8: 359.06
A9: PP-005 | B9: ALVA CUELLAR DUGLAS CONCEPCION | C9: 2 | D9: 346.66 | E9: 55.78 | F9: 402.44
A10: PP-006 | B10: ALVARADO BRINGAS MILUSKA CARLA | C10: 2 | D10: 417.59 | E10: 3.1 | F10: 420.69
A11: PP-007 | B11: ANTON ENICE | C11: 1 | D11: 270.37 | E11: 15.49 | F11: 285.86
A12: PP-008 | B12: APARCANA ROSADIO LUIS MIGUEL | C12: 2 | D12: 238.24 | E12: 15.49 | F12: 253.73
A13: PP-009 | B13: ASTO VARGAS HANS PIERRE | C13: 1 | D13: 161.95 | E13: 9.3 | F13: 171.25
A14: PP-010 | B14: AVENDAÑO SILVA MIRLEY JESUS | C14: 1 | D14: 76.29 | E14: 0 | F14: 76.29
A15: PP-011 | B15: AVILA JOEL ANTONIO | C15: 2 | D15: 346.66 | E15: 6.2 | F15: 352.86
A16: PP-012 | B16: AYAQUE LARICO ISAAC ALFREDO | C16: 2 | D16: 346.66 | E16: 9.3 | F16: 355.96
... A206: PP-202 | B206: PALOMINO CRISTIAN | C206: 2 | D206: 346.66 | E206: 12.4 | F206: 359.06
A207: PP-LAV | B207: LAVANDERIA PRONTOMATIK | C207: 1
A208: PP-000 | B208: SIN IDENTIFICAR | C208: 1 | D208: 265.41 | E208: 213.82 | F208: 479.23
A209: Total general | C209: 381 | D209: 60116.18 | E209: 4708.33 | F209: 64824.51

Sheet cuotas
A1: JUNTA DE PROPIETARIOS DEL EDIFICIO MULTIFAMILIAR "PACIFIK OCEAN TOWER"
A2: 20614642247
A3: Av. Bertolotto 850 - San Miguel
A5: codigo | B5: propietario | C5: predio | D5: saldo anterior | E5: 2026-01
A6: PP-000 | B6: SIN IDENTIFICAR | C6: E000 | D6: 897.99 | E6: 171.33
A7: PP-001 | B7: AJK ASOCIADOS SAC | C7: DEPA-1605 | D7: 377.02 | E7: 353.38
A8: PP-002 | B8: ALBAN MALACHE CHABELI | C8: DEPA-612 | D8: 395.44 | E8: 373.66
A9: PP-003 | B9: RUIZ JAVIER ALEJANDRO | C9: DEPA-811 | D9: 179.63 | E9: 168.13
A10: PP-004 | B10: ALEXANDER STRAHLE JURGEN | C10: DEPA-902 | D10: 0 | E10: 364.5
A11: PP-005 | B11: ALVA CUELLAR DUGLAS CONCEPCION | C11: DEPA-1205 | D11: 0 | E11: 397.23
A12: PP-006 | B12: ALVARADO BRINGAS MILUSKA CARLA | C12: DEPA-1001 | D12: 534.14 | E12: 506.22
A13: PP-007 | B13: ANTON ENICE | C13: DEPA-610 | D13: 1913.57 | E13: 296.71
A14: PP-008 | B14: APARCANA ROSADIO LUIS MIGUEL | C14: DEPA-606 | D14: 251.45 | E14: 244.18
A15: PP-009 | B15: ASTO VARGAS HANS PIERRE | C15: DEPA-1311 | D15: 3.34 | E15: 165.63
A16: PP-010 | B16: AVENDAÑO SILVA MIRLEY JESUS | C16: ESTA-087 | D16: 241.56 | E16: 76.29
A17: PP-011 | B17: AVILA JOEL ANTONIO | C17: DEPA-804 | D17: 0 | E17: 352.6
... A152: PP-146 | B152: ROSAS JHENIFER | C152: DEPA-204 | D152: 115.8 | E152: 198.92
A153: PP-147 | B153: RUBIANO NELSON | C153: DEPA-1507 | D153: 2128.87 | E153: 334.11 | G153: =+D153+E153 -> 2462.98 | H153: =+G153*1.05 -> 2586.129 | J153: 2496.05
A154: PP-148 | B154: RUIZ GUTIERREZ ROSA | C154: DEPA-704 | D154: 0 | E154: 361.53
A155: PP-149 | B155: SAAVEDRA MACHUCA DANY ELVIS | C155: DEPA-603 | D155: 2607.02 | E155: 273.34
A156: PP-150 | B156: SALINAS SOUZA CARLOS ENRIQUE JOSE ALFREDO | C156: DEPA-1106 | D156: 0 | E156: 260.33
A157: PP-151 | B157: SALVADOR NILS | C157: DEPA-1105 | D157: 790.89 | E157: 374.41
A158: PP-152 | B158: SAMANAMUD LOZANO NADIA | C158: DEPA-906 | D158: 1536.73 | E158: 241.21
A159: PP-153 | B159: SANCHEZ DIAZ RUBEN | C159: DEPA-711 | D159: 0 | E159: 173.85
A160: PP-154 | B160: SANCHEZ-SALAZAR OLCESE GLADYS MARIELA | C160: DEPA-206 | D160: 1080.96 | E160: 338.77
A161: PP-155 | B161: SANDOVAL AMASIFUEN EDWARD | C161: DEPA-1410 | D161: 835.59 | E161: 406.16
A162: PP-156 | B162: MONTES DE OCA BRAMOSIO MARIA GABY | C162: DEPA-1404 | D162: 0 | E162: 346.65
A163: PP-157 | B163: BUSTAMANTE EDUARDO - SARMIENTO INGRID | C163: DEPA-405 | D163: 414.48 | E163: 404.03
A164: PP-158 | B164: MEDINA SARMIENTO JAVIER | C164: DEPA-311 | D164: 182.41 | E164: 179.8
A165: PP-159 | B165: SAUÑE PACCO JOSE OSWALDO | C165: DEPA-1707 | D165: 0 | E165: 352.6
... A208: PP-202 | B208: PALOMINO CRISTIAN | C208: DEPA-1303 | D208: 368.86 | E208: 349.63
A209: PP-LAV | B209: LAVANDERIA PRONTOMATIK | C209: PP-LAV

Sheet ingresos
A1: JUNTA DE PROPIETARIOS DEL EDIFICIO MULTIFAMILIAR "PACIFIK OCEAN TOWER"
A2: 20614642247
A3: Av. Bertolotto 850 - San Miguel
A5: Fecha | B5: Descripción operación | C5: Monto | D5: Operación - Número | E5: Referencia | F5: codigo PP | G5: periodo x aplicar
A6: 46023 | C6: 0 | D6: 0 | E6: 0 | F6: PP-000
A7: 46023 | B7: TRAN.CTAS.TERC.BM | C7: 30 | D7: 03209955 | E7: ROJAS CACERES VITHIA MARCELA | G7: cine
A8: 46023 | B8: TRANSF.BCO.INTERBANK | C8: 100 | D8: 02847819 | E8: ALVAREZ-SALAS-CARLOS | G8: arcade
A9: 46023 | B9: TRAN.CTAS.TERC.BM | C9: 200 | D9: 02928341 | E9: LIANG NN YANQIU | G9: arcade
A10: 46023 | B10: TRAN.CTAS.TERC.BM | C10: 269.33 | D10: 03617458 | E10: TUPAYACHI VALLENAS DENIS ALFREDO | F10: PP-173 | G10: periodo anterior
A11: 46023 | B11: TRAN.CTAS.TERC.BM | C11: 368.33 | D11: 08573454 | E11: LIANG YANQIU | F11: PP-096 | G11: periodo anterior
A12: 46023 | B12: TRANSF.BCO.BBVA | C12: 372.09 | D12: 02705227 | E12: GIANELLA LIZETH NEIRA BUSTAMANTE | F12: PP-127 | G12: periodo anterior
A13: 46024 | B13: TRAN.CTAS.TERC.BM | C13: 30 | D13: 00794655 | E13: MONTESINOS CAMPOS NATALY MAGDALENA | G13: cine
A14: 46024 | B14: TRAN.CTAS.TERC.BM | C14: 30 | D14: 04534099 | E14: CHAVEZ JULCAHUANCA VANESSA ZORAIDA | G14: cine
A15: 46024 | B15: TRAN.CTAS.TERC.BM | C15: 40 | D15: 04819680 | E15: VALLEBUONA MAYTA LUIS ALBERTO | G15: parrilla
A16: 46024 | B16: TRAN.CTAS.TERC.BM | C16: 380.25 | D16: 00791169 | E16: HUANAY MARTINEZ FRANZ CESAR | F16: PP-080 | G16: periodo anterior
A17: 46024 | B17: TRAN.CTAS.TERC.BM | C17: 385.97 | D17: 03006094 | E17: FERRER CODINA MILAGROS DE JESUS | F17: PP-053 | G17: periodo anterior
A18: 46024 | B18: TRAN.CTAS.TERC.BM | C18: 389.72 | D18: 05389544 | E18: VEGA DIESTRA DAVID VICTOR | F18: PP-180 | G18: periodo anterior
A19: 46024 | B19: TRAN.CTAS.TERC.BM | C19: 398.66 | D19: 05823344 | E19: FLORES GARCIA KATIUSKA TERESA | F19: PP-031 | G19: periodo anterior
A20: 46024 | B20: TRANSF.BCO.BBVA | C20: 404.62 | D20: 02696269 | E20: DIEGO HERNAN MORALES X | F20: PP-078 | G20: periodo anterior
A21: 46024 | B21: TRANSF.BCO.INTERBANK | C21: 410.58 | D21: 02419310 | E21: ENRIQUEZ-ILLESCAS-LAURA | F21: PP-089 | G21: periodo anterior
A22: 46025 | B22: TRANSF.BCO.BBVA | C22: 30 | D22: 02799173 | E22: VICTOR DANIEL DE LA CRUZ SOLO | G22: cine
A23: 46025 | B23: TRAN.CTAS.TERC.BM | C23: 30 | D23: 00681111 | E23: MILAGROS MERCEDES BARRIENTOS FLORES | G23: cine
A24: 46025 | B24: TRAN.CTAS.TERC.BM | C24: 391.13 | D24: 04257108 | E24: LI NN XIAN YI | F24: PP-189 | G24: periodo anterior
A25: 46027 | B25: TRAN.CTAS.TERC.BM | C25: 254.32 | D25: 04138284 | E25: depa 708 | F25: PP-136 | G25: periodo anterior
A26: 46027 | B26: TRAN.CTAS.TERC.BM | C26: 254.43 | D26: 01810104 | E26: LOCK GOVEA JOSE EDILBERTO | F26: PP-067 | G26: periodo anterior
A27: 46027 | B27: TRAN.CTAS.TERC.BM | C27: 365.88 | D27: 05568200 | E27: depa 807 | F27: PP-164 | G27: periodo anterior
A28: 46027 | B28: TRAN.CTAS.TERC.BM | C28: 365.88 | D28: 05171425 | E28: depa 807 | F28: PP-164 | G28: periodo anterior
A29: 46027 | B29: TRAN.CTAS.TERC.BM | C29: 403.63 | D29: 04733331 | E29: TRAN.CTAS.TERC.BM | F29: PP-151 | G29: periodo anterior
A30: 46027 | B30: TRANSF.BCO.INTERBANK | C30: 529.77 | D30: 02918078 | E30: CHUMPITAZ-JORDAN-GIANFRANCO | F30: PP-182 | G30: periodo anterior
A31: 46028 | B31: TRAN.CTAS.TERC.BM | C31: 40 | D31: 01167585 | E31: TOLOSA ALVAREZ WILKENDRY ANTONIO | G31: parrilla
A32: 46028 | B32: TRANSF.BCO.SCOTIABANK | C32: 186 | D32: 02838839 | E32: ROSA TUME ZEGARRA | F32: PP-123 | G32: periodo anterior
A33: 46028 | B33: TRAN.CTAS.TERC.BM | C33: 303.3 | D33: 06339795 | E33: CHAVEZ MYLADY | F33: PP-036 | G33: periodo anterior
A34: 46029 | B34: TRAN.CTAS.TERC.HK | C34: 77.76 | D34: 06000739 | E34: ORELLANA VARGAS CARMEN ROSA | F34: PP-123 | G34: 2026-01
A35: 46029 | B35: TRANSF.BCO.BBVA | C35: 170.93 | D35: 02314420 | E35: SANCHEZ-SALAZAR OLCESE GLADYS MARIELA | F35: PP-154 | G35: periodo anterior
A36: 46029 | B36: TRAN.CTAS.TERC.BM | C36: 170.93 | D36: 00142069 | E36: PAOLA FABIOLA QUI�ONES PONCE DE LEON | F36: PP-187 | G36: periodo anterior
A37: 46029 | B37: TRAN.CTAS.TERC.BM | C37: 383.1 | D37: 01158104 | E37: CASTILLA PEREZ CARMELA FERMINA | F37: PP-029 | G37: periodo anterior
A38: 46029 | B38: TRAN.CTAS.TERC.BM | C38: 392.97 | D38: 01049363 | E38: CASTILLA PEREZ CARMELA FERMINA | F38: PP-029 | G38: periodo anterior
A39: 46029 | B39: TRAN.CTAS.TERC.BM | C39: 393.7 | D39: 03385120 | E39: TRAN.CTAS.TERC.BM | F39: PP-085 | G39: periodo anterior
A40: 46030 | B40: TRAN.CTAS.TERC.BM | C40: 4.51 | D40: 03475750 | E40: DE-LA-CRUZ DELGADO WALTER | F40: PP-044 | G40: periodo anterior
A41: 46030 | B41: TRANSF.BCO.INTERBANK | C41: 40 | D41: 02904936 | E41: BELLIDO-GUILLEN-LINO | G41: parrilla
...

Sheet saldo
A1: JUNTA DE PROPIETARIOS DEL EDIFICIO MULTIFAMILIAR "PACIFIK OCEAN TOWER"
A2: 20614642247
A3: Av. Bertolotto 850 - San Miguel
A5: codigo | B5: propietario | C5: predio | D5: periodo anterior | E5: 2026-01 | F5: Saldo acumulado
A6: PP-001 | B6: AJK ASOCIADOS SAC | C6: DEPA-1605 | D6: =VLOOKUP($A6,cuotas!$A$5:$E$209,4,0)-SUMIFS(ingresos!$C:$C,ingresos!$F:$F,saldo!$A6,ingresos!$G:$G,saldo!D$5) -> 377.02 | E6: =VLOOKUP($A6,cuotas!$A$5:$E$209,5,0)-SUMIFS(ingresos!$C:$C,ingresos!$F:$F,saldo!$A6,ingresos!$G:$G,saldo!E$5) -> 353.38 | F6: =SUM(D6:E6) -> 730.4
A7: PP-002 | B7: ALBAN MALACHE CHABELI | C7: DEPA-612 | D7: =VLOOKUP($A7,cuotas!$A$5:$E$209,4,0)-SUMIFS(ingresos!$C:$C,ingresos!$F:$F,saldo!$A7,ingresos!$G:$G,saldo!D$5) -> 0 | E7: =VLOOKUP($A7,cuotas!$A$5:$E$209,5,0)-SUMIFS(ingresos!$C:$C,ingresos!$F:$F,saldo!$A7,ingresos!$G:$G,saldo!E$5) -> 0 | F7: =SUM(D7:E7) -> 0
A8: PP-003 | B8: RUIZ JAVIER ALEJANDRO | C8: DEPA-811 | D8: =VLOOKUP($A8,cuotas!$A$5:$E$209,4,0)-SUMIFS(ingresos!$C:$C,ingresos!$F:$F,saldo!$A8,ingresos!$G:$G,saldo!D$5) -> 0 | E8: =VLOOKUP($A8,cuotas!$A$5:$E$209,5,0)-SUMIFS(ingresos!$C:$C,ingresos!$F:$F,saldo!$A8,ingresos!$G:$G,saldo!E$5) -> 0 | F8: =SUM(D8:E8) -> 0
A9: PP-004 | B9: ALEXANDER STRAHLE JURGEN | C9: DEPA-902 | D9: =VLOOKUP($A9,cuotas!$A$5:$E$209,4,0)-SUMIFS(ingresos!$C:$C,ingresos!$F:$F,saldo!$A9,ingresos!$G:$G,saldo!D$5) -> 0 | E9: =VLOOKUP($A9,cuotas!$A$5:$E$209,5,0)-SUMIFS(ingresos!$C:$C,ingresos!$F:$F,saldo!$A9,ingresos!$G:$G,saldo!E$5) -> 364.5 | F9: =SUM(D9:E9) -> 364.5
A10: PP-005 | B10: ALVA CUELLAR DUGLAS CONCEPCION | C10: DEPA-1205 | D10: =VLOOKUP($A10,cuotas!$A$5:$E$209,4,0)-SUMIFS(ingresos!$C:$C,ingresos!$F:$F,saldo!$A10,ingresos!$G:$G,saldo!D$5) -> 0 | E10: =VLOOKUP($A10,cuotas!$A$5:$E$209,5,0)-SUMIFS(ingresos!$C:$C,ingresos!$F:$F,saldo!$A10,ingresos!$G:$G,saldo!E$5) -> 397.23 | F10: =SUM(D10:E10) -> 397.23
A11: PP-006 | B11: ALVARADO BRINGAS MILUSKA CARLA | C11: DEPA-1001 | D11: =VLOOKUP($A11,cuotas!$A$5:$E$209,4,0)-SUMIFS(ingresos!$C:$C,ingresos!$F:$F,saldo!$A11,ingresos!$G:$G,saldo!D$5) -> 0 | E11: =VLOOKUP($A11,cuotas!$A$5:$E$209,5,0)-SUMIFS(ingresos!$C:$C,ingresos!$F:$F,saldo!$A11,ingresos!$G:$G,saldo!E$5) -> 0 | F11: =SUM(D11:E11) -> 0
A12: PP-007 | B12: ANTON ENICE | C12: DEPA-610 | D12: =VLOOKUP($A12,cuotas!$A$5:$E$209,4,0)-SUMIFS(ingresos!$C:$C,ingresos!$F:$F,saldo!$A12,ingresos!$G:$G,saldo!D$5) -> 1913.57 | E12: =VLOOKUP($A12,cuotas!$A$5:$E$209,5,0)-SUMIFS(ingresos!$C:$C,ingresos!$F:$F,saldo!$A12,ingresos!$G:$G,saldo!E$5) -> 296.71 | F12: =SUM(D12:E12) -> 2210.28
A13: PP-008 | B13: APARCANA ROSADIO LUIS MIGUEL | C13: DEPA-606 | D13: =VLOOKUP($A13,cuotas!$A$5:$E$209,4,0)-SUMIFS(ingresos!$C:$C,ingresos!$F:$F,saldo!$A13,ingresos!$G:$G,saldo!D$5) -> 0 | E13: =VLOOKUP($A13,cuotas!$A$5:$E$209,5,0)-SUMIFS(ingresos!$C:$C,ingresos!$F:$F,saldo!$A13,ingresos!$G:$G,saldo!E$5) -> 0 | F13: =SUM(D13:E13) -> 0
A14: PP-009 | B14: ASTO VARGAS HANS PIERRE | C14: DEPA-1311 | D14: =VLOOKUP($A14,cuotas!$A$5:$E$209,4,0)-SUMIFS(ingresos!$C:$C,ingresos!$F:$F,saldo!$A14,ingresos!$G:$G,saldo!D$5) -> 3.34 | E14: =VLOOKUP($A14,cuotas!$A$5:$E$209,5,0)-SUMIFS(ingresos!$C:$C,ingresos!$F:$F,saldo!$A14,ingresos!$G:$G,saldo!E$5) -> 0 | F14: =SUM(D14:E14) -> 3.34
A15: PP-010 | B15: AVENDAÑO SILVA MIRLEY JESUS | C15: ESTA-087 | D15: =VLOOKUP($A15,cuotas!$A$5:$E$209,4,0)-SUMIFS(ingresos!$C:$C,ingresos!$F:$F,saldo!$A15,ingresos!$G:$G,saldo!D$5) -> 241.56 | E15: =VLOOKUP($A15,cuotas!$A$5:$E$209,5,0)-SUMIFS(ingresos!$C:$C,ingresos!$F:$F,saldo!$A15,ingresos!$G:$G,saldo!E$5) -> 76.29 | F15: =SUM(D15:E15) -> 317.85
A16: PP-011 | B16: AVILA JOEL ANTONIO | C16: DEPA-804 | D16: =VLOOKUP($A16,cuotas!$A$5:$E$209,4,0)-SUMIFS(ingresos!$C:$C,ingresos!$F:$F,saldo!$A16,ingresos!$G:$G,saldo!D$5) -> 0 | E16: =VLOOKUP($A16,cuotas!$A$5:$E$209,5,0)-SUMIFS(ingresos!$C:$C,ingresos!$F:$F,saldo!$A16,ingresos!$G:$G,saldo!E$5) -> 0 | F16: =SUM(D16:E16) -> 0
A17: PP-012 | B17: AYAQUE LARICO ISAAC ALFREDO | C17: DEPA-1602 | D17: =VLOOKUP($A17,cuotas!$A$5:$E$209,4,0)-SUMIFS(ingresos!$C:$C,ingresos!$F:$F,saldo!$A17,ingresos!$G:$G,saldo!D$5) -> 0 | E17: =VLOOKUP($A17,cuotas!$A$5:$E$209,5,0)-SUMIFS(ingresos!$C:$C,ingresos!$F:$F,saldo!$A17,ingresos!$G:$G,saldo!E$5) -> 0 | F17: =SUM(D17:E17) -> 0
... A208: PP-LAV | B208: LAVANDERIA PRONTOMATIK | C208: PP-LAV | D208: =VLOOKUP($A208,cuotas!$A$5:$E$209,4,0)-SUMIFS(ingresos!$C:$C,ingresos!$F:$F,saldo!$A208,ingresos!$G:$G,saldo!D$5) -> 0 | E208: =VLOOKUP($A208,cuotas!$A$5:$E$209,5,0)-SUMIFS(ingresos!$C:$C,ingresos!$F:$F,saldo!$A208,ingresos!$G:$G,saldo!E$5) -> 0 | F208: =SUM(D208:E208) -> 0

Sheet reciboxmes
A1: JUNTA DE PROPIETARIOS DEL EDIFICIO MULTIFAMILIAR "PACIFIK OCEAN TOWER"
A2: 20614642247
A3: Av. Bertolotto 850 - San Miguel
A5: RECIBO MANTENIMIENTO | H5: cuota del mes | I5: =VLOOKUP($D$19,cuota_resumen!$A:$F,6,0) -> 174.35
A7: Periodo | C7: Fecha emisión | E7: Fecha vencimiento | G7: Consumo agua (m3) | I7: Codigo Propietario
A8: 2026-febrero | C8: 46060 | E8: 46075 | G8: =IFERROR(VLOOKUP($C$22,consumo_agua!$A$7:$AA$202,25,0),0) -> 4 | I8: =$D$19 -> PP-038
A10: Titular 1 | C10: =VLOOKUP($I$8,cuotas!$A:$B,2,0) -> CHIROQUE FLOR LOZANO
A12: Titular 2
A14: Arrendatario
C19: CODIGO | D19: PP-038
C21: Predio | D21: % PARTICIPACIÓN | E21: VALOR CUOTA | F21: S/. AGUA CONSUMO | G21: SUMA
C22: DEPA-1011 | D22: 0.0026939 | E22: 161.95 | F22: 12.4 | G22: 174.35
C23: Total general | D23: 0.0026939 | E23: 161.95 | F23: 12.4 | G23: 174.35
A37: Informacion historica:
A38: cuotas emitidas | D38: abonos recibidos | H38: saldo por cobrar al mes anterior
A39: periodos ant. | B39: =VLOOKUP($D$19,cuotas!$A:$E,4,0) -> 175.13 | D39: codigo PP | E39: PP-038 | H39: periodos ant. | I39: =VLOOKUP($D$19,saldo!$A:$E,4,0) -> -7.37
A40: 46023 | B40: =VLOOKUP($D$19,cuotas!$A:$E,5,0) -> 171.22 | H40: 46023 | I40: =VLOOKUP($D$19,saldo!$A:$E,5,0) -> 171.22
D41: fechas | E41: Montos
B42: =SUM(B39:B41) -> 346.35 | D42: 46030 | E42: 182.5 | I42: =SUM(I39:I41) -> 163.85
D43: Total general | E43: 182.5 | H43: =IF($I$42<0,"*saldo a favor del propietario","-") -> -
A49: Recibo digital elaborado por:
A50: ALGORITMO ADMIN
