Workbook
Name agua_consumo: [1]agua!$B$10:$BZ$65
Name pp_anual26: pres!$C$2

Sheet pres
B2: PRESUPUESTO X DISTRIBUIR | C2: 60116
B4: agua potable 2025-12 | C4: =4776.4-900 -> 3876.4
C5: =SUM(C2:C4) -> 63992.4

Sheet consumo_agua
H1: recibo | I1: 4713.4 | L1: 4636.5 | O1: 5266.7 | R1: 2972.4 | U1: 3793.1 | X1: 3876.4
H2: m3 conteo | I2: =$G$203 -> 1262.229 | J2: <promedio | L2: =J203 -> 1115.961 | M2: <promedio | O2: =M203 -> 824.779 | P2: <promedio | R2: =P203 -> 1035.538 | U2: =S203 -> 1272.95 | X2: =V203 -> 1302.895 | Z2: <promedio
H3: c.u. x m3 | I3: =ROUND(I1/I2,4) -> 3.7342 | L3: =ROUND(L1/L2,4) -> 4.1547 | O3: =ROUND(O1/O2,4) -> 6.3856 | R3: =ROUND(R1/R2,4) -> 2.8704 | U3: =ROUND(U1/U2,4) -> 2.9798 | X3: =ROUND(X1/X2,4) -> 2.9752
A4: JUNTA DE PROPIETARIOS DEL EDIFICIO MULTIFAMILIAR " PACIFIK OCEAN TOWER"
A5: Historico - consumo de agua
A7: DEPAF | B7: MAYO | C7: consumo> | D7: JUNIO | E7: consumo> | F7: JULIO | G7: consumo> | H7: AGOSTO | I7: PEN-agua | J7: consumo> | K7: SET | L7: PEN-agua | M7: consumo> | N7: OCT | O7: PEN-agua | P7: consumo> | Q7: NOV | R7: PEN-agua | S7: consumo> | T7: DIC | U7: PEN-agua | V7: consumo> | W7: 46023 | X7: PEN-agua
A8: DEPA-101 | B8: 800 | C8: =D8-B8 -> 21 | D8: 821 | E8: =F8-D8 -> 22 | F8: 843 | G8: =H8-F8 -> 27 | H8: 870 | I8: =ROUND(G8*$I$3,2) -> 100.82 | J8: =K8-H8 -> 23 | K8: 893 | L8: =ROUND(J8*$L$3,2) -> 95.56 | M8: =N8-K8 -> 18 | N8: 911 | O8: =ROUND(M8*$O$3,2) -> 114.94 | P8: =Q8-N8 -> 19 | Q8: 930 | R8: =ROUND(P8*$R$3,2) -> 54.54 | S8: =+T8-Q8 -> 22 | T8: 952 | U8: =ROUND(S8*$U$3,2) -> 65.56 | V8: =+W8-T8 -> 24 | W8: 976 | X8: =V8*$X$3 -> 71.4048
A9: DEPA-102 | B9: 287 | C9: =D9-B9 -> 7 | D9: 294 | E9: =F9-D9 -> 4 | F9: 298 | G9: =H9-F9 -> 7 | H9: 305 | I9: =ROUND(G9*$I$3,2) -> 26.14 | J9: =K9-H9 -> 4 | K9: 309 | L9: =ROUND(J9*$L$3,2) -> 16.62 | M9: =N9-K9 -> 3 | N9: 312 | O9: =ROUND(M9*$O$3,2) -> 19.16 | P9: =Q9-N9 -> 3 | Q9: 315 | R9: =ROUND(P9*$R$3,2) -> 8.61 | S9: =+T9-Q9 -> 2 | T9: 317 | U9: =ROUND(S9*$U$3,2) -> 5.96 | V9: =+W9-T9 -> 2 | W9: 319 | X9: =V9*$X$3 -> 5.9504
A10: DEPA-103 | B10: 51 | C10: =D10-B10 -> 0 | D10: 51 | E10: =F10-D10 -> 0 | F10: 51 | G10: =H10-F10 -> 0 | H10: 51 | I10: =ROUND(G10*$I$3,2) -> 0 | J10: =K10-H10 -> 0 | K10: 51 | L10: =ROUND(J10*$L$3,2) -> 0 | M10: =N10-K10 -> 0 | N10: 51 | O10: =ROUND(M10*$O$3,2) -> 0 | P10: =Q10-N10 -> 0 | Q10: 51 | R10: =ROUND(P10*$R$3,2) -> 0 | S10: =+T10-Q10 -> 0 | T10: 51 | U10: =ROUND(S10*$U$3,2) -> 0 | V10: =+W10-T10 -> 0 | W10: 51 | X10: =V10*$X$3 -> 0
A11: DEPA-104 | B11: 327 | C11: =D11-B11 -> 5 | D11: 332 | E11: =F11-D11 -> 6 | F11: 338 | G11: =H11-F11 -> 7 | H11: 345 | I11: =ROUND(G11*$I$3,2) -> 26.14 | J11: =K11-H11 -> 5 | K11: 350 | L11: =ROUND(J11*$L$3,2) -> 20.77 | M11: =N11-K11 -> 5 | N11: 355 | O11: =ROUND(M11*$O$3,2) -> 31.93 | P11: =Q11-N11 -> 9 | Q11: 364 | R11: =ROUND(P11*$R$3,2) -> 25.83 | S11: =+T11-Q11 -> 8 | T11: 372 | U11: =ROUND(S11*$U$3,2) -> 23.84 | V11: =+W11-T11 -> 12 | W11: 384 | X11: =V11*$X$3 -> 35.7024
A12: DEPA-105 | B12: 532 | C12: =D12-B12 -> 10 | D12: 542 | E12: =F12-D12 -> 12 | F12: 554 | G12: =H12-F12 -> 8 | H12: 562 | I12: =ROUND(G12*$I$3,2) -> 29.87 | J12: =K12-H12 -> 13 | K12: 575 | L12: =ROUND(J12*$L$3,2) -> 54.01 | M12: =N12-K12 -> 10 | N12: 585 | O12: =ROUND(M12*$O$3,2) -> 63.86 | P12: =Q12-N12 -> 14 | Q12: 599 | R12: =ROUND(P12*$R$3,2) -> 40.19 | S12: =+T12-Q12 -> 13 | T12: 612 | U12: =ROUND(S12*$U$3,2) -> 38.74 | V12: =+W12-T12 -> 22 | W12: 634 | X12: =V12*$X$3 -> 65.4544
A13: DEPA-106 | B13: 396 | C13: =D13-B13 -> 0 | D13: 396 | E13: =F13-D13 -> 0 | F13: 396 | G13: =H13-F13 -> 1 | H13: 397 | I13: =ROUND(G13*$I$3,2) -> 3.73 | J13: =K13-H13 -> 2 | K13: 399 | L13: =ROUND(J13*$L$3,2) -> 8.31 | M13: =N13-K13 -> 5 | N13: 404 | O13: =ROUND(M13*$O$3,2) -> 31.93 | P13: =Q13-N13 -> 8 | Q13: 412 | R13: =ROUND(P13*$R$3,2) -> 22.96 | S13: =+T13-Q13 -> 9 | T13: 421 | U13: =ROUND(S13*$U$3,2) -> 26.82 | V13: =+W13-T13 -> 8 | W13: 429 | X13: =V13*$X$3 -> 23.8016
A14: DEPA-107 | B14: 25 | C14: =D14-B14 -> 0 | D14: 25 | E14: =F14-D14 -> 1 | F14: 26 | G14: =H14-F14 -> 0 | H14: 26 | I14: =ROUND(G14*$I$3,2) -> 0 | J14: =K14-H14 -> 0 | K14: 26 | L14: =ROUND(J14*$L$3,2) -> 0 | M14: =N14-K14 -> 1 | N14: 27 | O14: =ROUND(M14*$O$3,2) -> 6.39 | P14: =Q14-N14 -> 1 | Q14: 28 | R14: =ROUND(P14*$R$3,2) -> 2.87 | S14: =+T14-Q14 -> 0 | T14: 28 | U14: =ROUND(S14*$U$3,2) -> 0 | V14: =+W14-T14 -> 1 | W14: 29 | X14: =V14*$X$3 -> 2.9752
A15: DEPA-201 | B15: 128 | C15: =D15-B15 -> 8 | D15: 136 | E15: =F15-D15 -> 6 | F15: 142 | G15: =H15-F15 -> 11 | H15: 153 | I15: =ROUND(G15*$I$3,2) -> 41.08 | J15: =K15-H15 -> 8 | K15: 161 | L15: =ROUND(J15*$L$3,2) -> 33.24 | M15: =N15-K15 -> 4 | N15: 165 | O15: =ROUND(M15*$O$3,2) -> 25.54 | P15: =Q15-N15 -> 6 | Q15: 171 | R15: =ROUND(P15*$R$3,2) -> 17.22 | S15: =+T15-Q15 -> 9 | T15: 180 | U15: =ROUND(S15*$U$3,2) -> 26.82 | V15: =+W15-T15 -> 11 | W15: 191 | X15: =V15*$X$3 -> 32.7272
A16: DEPA-202 | B16: 95 | C16: =D16-B16 -> 6 | D16: 101 | E16: =F16-D16 -> 4 | F16: 105 | G16: =H16-F16 -> 6 | H16: 111 | I16: =ROUND(G16*$I$3,2) -> 22.41 | J16: =K16-H16 -> 3 | K16: 114 | L16: =ROUND(J16*$L$3,2) -> 12.46 | M16: =N16-K16 -> 4 | N16: 118 | O16: =ROUND(M16*$O$3,2) -> 25.54 | P16: =Q16-N16 -> 4 | Q16: 122 | R16: =ROUND(P16*$R$3,2) -> 11.48 | S16: =+T16-Q16 -> 5 | T16: 127 | U16: =ROUND(S16*$U$3,2) -> 14.9 | V16: =+W16-T16 -> 6 | W16: 133 | X16: =V16*$X$3 -> 17.8512
A17: DEPA-203 | B17: 234 | C17: =D17-B17 -> 4 | D17: 238 | E17: =F17-D17 -> 4 | F17: 242 | G17: =H17-F17 -> 8 | H17: 250 | I17: =ROUND(G17*$I$3,2) -> 29.87 | J17: =K17-H17 -> 3 | K17: 253 | L17: =ROUND(J17*$L$3,2) -> 12.46 | M17: =N17-K17 -> 4 | N17: 257 | O17: =ROUND(M17*$O$3,2) -> 25.54 | P17: =Q17-N17 -> 8 | Q17: 265 | R17: =ROUND(P17*$R$3,2) -> 22.96 | S17: =+T17-Q17 -> 55 | T17: 320 | U17: =ROUND(S17*$U$3,2) -> 163.89 | V17: =+W17-T17 -> 29 | W17: 349 | X17: =V17*$X$3 -> 86.2808 | Y17: *pablo
A18: DEPA-204 | B18: 145 | C18: =D18-B18 -> 4 | D18: 149 | E18: =F18-D18 -> 5 | F18: 154 | G18: =H18-F18 -> 7 | H18: 161 | I18: =ROUND(G18*$I$3,2) -> 26.14 | J18: =K18-H18 -> 5 | K18: 166 | L18: =ROUND(J18*$L$3,2) -> 20.77 | M18: =N18-K18 -> 4 | N18: 170 | O18: =ROUND(M18*$O$3,2) -> 25.54 | P18: =Q18-N18 -> 4 | Q18: 174 | R18: =ROUND(P18*$R$3,2) -> 11.48 | S18: =+T18-Q18 -> 6 | T18: 180 | U18: =ROUND(S18*$U$3,2) -> 17.88 | V18: =+W18-T18 -> 5 | W18: 185 | X18: =V18*$X$3 -> 14.876
A19: DEPA-205 | B19: 157 | C19: =D19-B19 -> 8 | D19: 165 | E19: =F19-D19 -> 7 | F19: 172 | G19: =H19-F19 -> 7 | H19: 179 | I19: =ROUND(G19*$I$3,2) -> 26.14 | J19: =K19-H19 -> 7 | K19: 186 | L19: =ROUND(J19*$L$3,2) -> 29.08 | M19: =N19-K19 -> 5 | N19: 191 | O19: =ROUND(M19*$O$3,2) -> 31.93 | P19: =Q19-N19 -> 3 | Q19: 194 | R19: =ROUND(P19*$R$3,2) -> 8.61 | S19: =+T19-Q19 -> 8 | T19: 202 | U19: =ROUND(S19*$U$3,2) -> 23.84 | V19: =+W19-T19 -> 9 | W19: 211 | X19: =V19*$X$3 -> 26.7768
A20: DEPA-206 | B20: 131 | C20: =D20-B20 -> 4 | D20: 135 | E20: =F20-D20 -> 4 | F20: 139 | G20: =H20-F20 -> 7 | H20: 146 | I20: =ROUND(G20*$I$3,2) -> 26.14 | J20: =K20-H20 -> 5 | K20: 151 | L20: =ROUND(J20*$L$3,2) -> 20.77 | M20: =N20-K20 -> 3 | N20: 154 | O20: =ROUND(M20*$O$3,2) -> 19.16 | P20: =Q20-N20 -> 2 | Q20: 156 | R20: =ROUND(P20*$R$3,2) -> 5.74 | S20: =+T20-Q20 -> 0 | T20: 156 | U20: =ROUND(S20*$U$3,2) -> 0 | V20: =+W20-T20 -> 1 | W20: 157 | X20: =V20*$X$3 -> 2.9752
A21: DEPA-207 | B21: 196 | C21: =D21-B21 -> 4 | D21: 200 | E21: =F21-D21 -> 4 | F21: 204 | G21: =H21-F21 -> 5 | H21: 209 | I21: =ROUND(G21*$I$3,2) -> 18.67 | J21: =K21-H21 -> 4 | K21: 213 | L21: =ROUND(J21*$L$3,2) -> 16.62 | M21: =N21-K21 -> 3 | N21: 216 | O21: =ROUND(M21*$O$3,2) -> 19.16 | P21: =Q21-N21 -> 5 | Q21: 221 | R21: =ROUND(P21*$R$3,2) -> 14.35 | S21: =+T21-Q21 -> 0 | T21: 221 | U21: =ROUND(S21*$U$3,2) -> 0 | V21: =+W21-T21 -> 7 | W21: 228 | X21: =V21*$X$3 -> 20.8264
A22: DEPA-208 | B22: 258 | C22: =D22-B22 -> 9 | D22: 267 | E22: =F22-D22 -> 9 | F22: 276 | G22: =H22-F22 -> 5 | H22: 281 | I22: =ROUND(G22*$I$3,2) -> 18.67 | J22: =K22-H22 -> 12 | K22: 293 | L22: =ROUND(J22*$L$3,2) -> 49.86 | M22: =N22-K22 -> 5 | N22: 298 | O22: =ROUND(M22*$O$3,2) -> 31.93 | P22: =Q22-N22 -> 8 | Q22: 306 | R22: =ROUND(P22*$R$3,2) -> 22.96 | S22: =+T22-Q22 -> 10 | T22: 316 | U22: =ROUND(S22*$U$3,2) -> 29.8 | V22: =+W22-T22 -> 9 | W22: 325 | X22: =V22*$X$3 -> 26.7768
A23: DEPA-209 | B23: 14 | C23: =D23-B23 -> 1 | D23: 15 | E23: =F23-D23 -> 1 | F23: 16 | G23: =H23-F23 -> 0 | H23: 16 | I23: =ROUND(G23*$I$3,2) -> 0 | J23: =K23-H23 -> 1 | K23: 17 | L23: =ROUND(J23*$L$3,2) -> 4.15 | M23: =N23-K23 -> 0 | N23: 17 | O23: =ROUND(M23*$O$3,2) -> 0 | P23: =Q23-N23 -> 1 | Q23: 18 | R23: =ROUND(P23*$R$3,2) -> 2.87 | S23: =+T23-Q23 -> 1 | T23: 19 | U23: =ROUND(S23*$U$3,2) -> 2.98 | V23: =+W23-T23 -> 0 | W23: 19 | X23: =V23*$X$3 -> 0
A24: DEPA-210 | B24: 332.49 | C24: =D24-B24 -> 16.86 | D24: 349.35 | E24: =F24-D24 -> 18.18 | F24: 367.53 | G24: =H24-F24 -> 15.545 | H24: 383.075 | I24: =ROUND(G24*$I$3,2) -> 58.05 | J24: =K24-H24 -> 16.925 | K24: 400 | L24: =ROUND(J24*$L$3,2) -> 70.32 | M24: =N24-K24 -> 13.082 | N24: 413.082 | O24: =ROUND(M24*$O$3,2) -> 83.54 | P24: =Q24-N24 -> 14.926 | Q24: 428.008 | R24: =ROUND(P24*$R$3,2) -> 42.84 | S24: =+T24-Q24 -> 3.567 | T24: 431.575 | U24: =ROUND(S24*$U$3,2) -> 10.63 | V24: =+W24-T24 -> 8.425 | W24: 440 | X24: =V24*$X$3 -> 25.06606
A25: DEPA-301 | B25: 72 | C25: =D25-B25 -> 1 | D25: 73 | E25: =F25-D25 -> 1 | F25: 74 | G25: =H25-F25 -> 2 | H25: 76 | I25: =ROUND(G25*$I$3,2) -> 7.47 | J25: =K25-H25 -> 1 | K25: 77 | L25: =ROUND(J25*$L$3,2) -> 4.15 | M25: =N25-K25 -> 0 | N25: 77 | O25: =ROUND(M25*$O$3,2) -> 0 | P25: =Q25-N25 -> 1 | Q25: 78 | R25: =ROUND(P25*$R$3,2) -> 2.87 | S25: =+T25-Q25 -> 0 | T25: 78 | U25: =ROUND(S25*$U$3,2) -> 0 | V25: =+W25-T25 -> 0 | W25: 78 | X25: =V25*$X$3 -> 0
A26: DEPA-302 | B26: 12 | C26: =D26-B26 -> 6 | D26: 18 | E26: =F26-D26 -> 4 | F26: 22 | G26: =H26-F26 -> 5 | H26: 27 | I26: =ROUND(G26*$I$3,2) -> 18.67 | J26: =K26-H26 -> 5 | K26: 32 | L26: =ROUND(J26*$L$3,2) -> 20.77 | M26: =N26-K26 -> 5 | N26: 37 | O26: =ROUND(M26*$O$3,2) -> 31.93 | P26: =Q26-N26 -> 9 | Q26: 46 | R26: =ROUND(P26*$R$3,2) -> 25.83 | S26: =+T26-Q26 -> 12 | T26: 58 | U26: =ROUND(S26*$U$3,2) -> 35.76 | V26: =+W26-T26 -> 11 | W26: 69 | X26: =V26*$X$3 -> 32.7272
A27: DEPA-303 | B27: 58 | C27: =D27-B27 -> 0 | D27: 58 | E27: =F27-D27 -> 0 | F27: 58 | G27: =H27-F27 -> 3 | H27: 61 | I27: =ROUND(G27*$I$3,2) -> 11.2 | J27: =K27-H27 -> 0 | K27: 61 | L27: =ROUND(J27*$L$3,2) -> 0 | M27: =N27-K27 -> 0 | N27: 61 | O27: =ROUND(M27*$O$3,2) -> 0 | P27: =Q27-N27 -> 1 | Q27: 62 | R27: =ROUND(P27*$R$3,2) -> 2.87 | S27: =+T27-Q27 -> 0 | T27: 62 | U27: =ROUND(S27*$U$3,2) -> 0 | V27: =+W27-T27 -> 1 | W27: 63 | X27: =V27*$X$3 -> 2.9752
A28: DEPA-304 | B28: 434 | C28: =D28-B28 -> 13 | D28: 447 | E28: =F28-D28 -> 13 | F28: 460 | G28: =H28-F28 -> 13 | H28: 473 | I28: =ROUND(G28*$I$3,2) -> 48.54 | J28: =K28-H28 -> 12 | K28: 485 | L28: =ROUND(J28*$L$3,2) -> 49.86 | M28: =N28-K28 -> 7 | N28: 492 | O28: =ROUND(M28*$O$3,2) -> 44.7 | P28: =Q28-N28 -> 6 | Q28: 498 | R28: =ROUND(P28*$R$3,2) -> 17.22 | S28: =+T28-Q28 -> 2 | T28: 500 | U28: =ROUND(S28*$U$3,2) -> 5.96 | V28: =+W28-T28 -> 4 | W28: 504 | X28: =V28*$X$3 -> 11.9008
A29: DEPA-305 | B29: 60.11 | C29: =D29-B29 -> 4.28 | D29: 64.39 | E29: =F29-D29 -> 4.77 | F29: 69.16 | G29: =H29-F29 -> 5.735 | H29: 74.895 | I29: =ROUND(G29*$I$3,2) -> 21.42 | J29: =K29-H29 -> 2.581 | K29: 77.476 | L29: =ROUND(J29*$L$3,2) -> 10.72 | M29: =N29-K29 -> 2.935 | N29: 80.411 | O29: =ROUND(M29*$O$3,2) -> 18.74 | P29: =Q29-N29 -> 4.589 | Q29: 85 | R29: =ROUND(P29*$R$3,2) -> 13.17 | S29: =+T29-Q29 -> 5.048 | T29: 90.048 | U29: =ROUND(S29*$U$3,2) -> 15.04 | V29: =+W29-T29 -> 5.952 | W29: 96 | X29: =V29*$X$3 -> 17.70839
... A122: DEPA-1103 | B122: 210 | C122: =D122-B122 -> 4 | D122: 214 | E122: =F122-D122 -> 4 | F122: 218 | G122: =H122-F122 -> 9 | H122: 227 | I122: =ROUND(G122*$I$3,2) -> 33.61 | J122: =K122-H122 -> 3 | K122: 230 | L122: =ROUND(J122*$L$3,2) -> 12.46 | M122: =N122-K122 -> 2 | N122: 232 | O122: =ROUND(M122*$O$3,2) -> 12.77 | P122: =Q122-N122 -> 4 | Q122: 236 | R122: =ROUND(P122*$R$3,2) -> 11.48 | S122: =+T122-Q122 -> 5 | T122: 241 | U122: =ROUND(S122*$U$3,2) -> 14.9 | V122: =+W122-T122 -> 10 | W122: 251 | X122: =V122*$X$3 -> 29.752
A123: DEPA-1104 | B123: 298 | C123: =D123-B123 -> 5 | D123: 303 | E123: =F123-D123 -> 4 | F123: 307 | G123: 5 | H123: 62 | I123: =ROUND(G123*$I$3,2) -> 18.67 | J123: =K123-H123 -> 13 | K123: 75 | L123: =ROUND(J123*$L$3,2) -> 54.01 | M123: =N123-K123 -> 9 | N123: 84 | O123: =ROUND(M123*$O$3,2) -> 57.47 | P123: =Q123-N123 -> 11 | Q123: 95 | R123: =ROUND(P123*$R$3,2) -> 31.57 | S123: =+T123-Q123 -> 12 | T123: 107 | U123: =ROUND(S123*$U$3,2) -> 35.76 | V123: =+W123-T123 -> 12 | W123: 119 | X123: =V123*$X$3 -> 35.7024 | Z123: *medidor nuevo val. 25/08/2025
A124: DEPA-1105 | B124: 380.08 | C124: =D124-B124 -> 10.82 | D124: 390.9 | E124: =F124-D124 -> 9.63 | F124: 400.53 | G124: =H124-F124 -> 11.706 | H124: 412.236 | I124: =ROUND(G124*$I$3,2) -> 43.71 | J124: =K124-H124 -> 12.277 | K124: 424.513 | L124: =ROUND(J124*$L$3,2) -> 51.01 | M124: =N124-K124 -> 8.038 | N124: 432.551 | O124: =ROUND(M124*$O$3,2) -> 51.33 | P124: =Q124-N124 -> 7.449 | Q124: 440 | R124: =ROUND(P124*$R$3,2) -> 21.38 | S124: =+T124-Q124 -> 12.669 | T124: 452.669 | U124: =ROUND(S124*$U$3,2) -> 37.75 | V124: =+W124-T124 -> 9.331 | W124: 462 | X124: =V124*$X$3 -> 27.761591
A125: DEPA-1106 | B125: 35 | C125: =D125-B125 -> 1 | D125: 36 | E125: =F125-D125 -> 0 | F125: 36 | G125: =H125-F125 -> 1 | H125: 37 | I125: =ROUND(G125*$I$3,2) -> 3.73 | J125: =K125-H125 -> 0 | K125: 37 | L125: =ROUND(J125*$L$3,2) -> 0 | M125: =N125-K125 -> 0 | N125: 37 | O125: =ROUND(M125*$O$3,2) -> 0 | P125: =Q125-N125 -> 1 | Q125: 38 | R125: =ROUND(P125*$R$3,2) -> 2.87 | S125: =+T125-Q125 -> 0 | T125: 38 | U125: =ROUND(S125*$U$3,2) -> 0 | V125: =+W125-T125 -> 0 | W125: 38 | X125: =V125*$X$3 -> 0
A126: DEPA-1107 | B126: 288 | C126: =D126-B126 -> 5 | D126: 293 | E126: =F126-D126 -> 9 | F126: 302 | G126: =H126-F126 -> 8 | H126: 310 | I126: =ROUND(G126*$I$3,2) -> 29.87 | J126: =K126-H126 -> 8 | K126: 318 | L126: =ROUND(J126*$L$3,2) -> 33.24 | M126: =N126-K126 -> 3 | N126: 321 | O126: =ROUND(M126*$O$3,2) -> 19.16 | P126: =Q126-N126 -> 5 | Q126: 326 | R126: =ROUND(P126*$R$3,2) -> 14.35 | S126: =+T126-Q126 -> 9 | T126: 335 | U126: =ROUND(S126*$U$3,2) -> 26.82 | V126: =+W126-T126 -> 8 | W126: 343 | X126: =V126*$X$3 -> 23.8016
A127: DEPA-1108 | B127: 137 | C127: =D127-B127 -> 2 | D127: 139 | E127: =F127-D127 -> 3 | F127: 142 | G127: =H127-F127 -> 5 | H127: 147 | I127: =ROUND(G127*$I$3,2) -> 18.67 | J127: =K127-H127 -> 2 | K127: 149 | L127: =ROUND(J127*$L$3,2) -> 8.31 | M127: =N127-K127 -> 2 | N127: 151 | O127: =ROUND(M127*$O$3,2) -> 12.77 | P127: =Q127-N127 -> 3 | Q127: 154 | R127: =ROUND(P127*$R$3,2) -> 8.61 | S127: =+T127-Q127 -> 3 | T127: 157 | U127: =ROUND(S127*$U$3,2) -> 8.94 | V127: =+W127-T127 -> 3 | W127: 160 | X127: =V127*$X$3 -> 8.9256
A128: DEPA-1109 | B128: 199 | C128: =D128-B128 -> 4 | D128: 203 | E128: =F128-D128 -> 3 | F128: 206 | G128: =H128-F128 -> 5 | H128: 211 | I128: =ROUND(G128*$I$3,2) -> 18.67 | J128: =K128-H128 -> 4 | K128: 215 | L128: =ROUND(J128*$L$3,2) -> 16.62 | M128: =N128-K128 -> 3 | N128: 218 | O128: =ROUND(M128*$O$3,2) -> 19.16 | P128: =Q128-N128 -> 3 | Q128: 221 | R128: =ROUND(P128*$R$3,2) -> 8.61 | S128: =+T128-Q128 -> 4 | T128: 225 | U128: =ROUND(S128*$U$3,2) -> 11.92 | V128: =+W128-T128 -> 2 | W128: 227 | X128: =V128*$X$3 -> 5.9504
A129: DEPA-1110 | B129: 278.12 | C129: =D129-B129 -> 5.13 | D129: 283.25 | E129: =F129-D129 -> 6.05 | F129: 289.3 | G129: =H129-F129 -> 7.15 | H129: 296.45 | I129: =ROUND(G129*$I$3,2) -> 26.7 | J129: =K129-H129 -> 5.854 | K129: 302.304 | L129: =ROUND(J129*$L$3,2) -> 24.32 | M129: =N129-K129 -> 4.304 | N129: 306.608 | O129: =ROUND(M129*$O$3,2) -> 27.48 | P129: =Q129-N129 -> 4.392 | Q129: 311 | R129: =ROUND(P129*$R$3,2) -> 12.61 | S129: =+T129-Q129 -> 7.308 | T129: 318.308 | U129: =ROUND(S129*$U$3,2) -> 21.78 | V129: =+W129-T129 -> 4.692 | W129: 323 | X129: =V129*$X$3 -> 13.959638
A130: DEPA-1111 | B130: 141.87 | C130: =D130-B130 -> 7 | D130: 148.87 | E130: =F130-D130 -> 6.35 | F130: 155.22 | G130: =H130-F130 -> 6.582 | H130: 161.802 | I130: =ROUND(G130*$I$3,2) -> 24.58 | J130: =K130-H130 -> 6.058 | K130: 167.86 | L130: =ROUND(J130*$L$3,2) -> 25.17 | M130: =N130-K130 -> 4.032 | N130: 171.892 | O130: =ROUND(M130*$O$3,2) -> 25.75 | P130: =Q130-N130 -> 5.108 | Q130: 177 | R130: =ROUND(P130*$R$3,2) -> 14.66 | S130: =+T130-Q130 -> 6.588 | T130: 183.588 | U130: =ROUND(S130*$U$3,2) -> 19.63 | V130: =+W130-T130 -> 6.412 | W130: 190 | X130: =V130*$X$3 -> 19.076982
A131: DEPA-1112 | B131: 239 | C131: =D131-B131 -> 18 | D131: 257 | E131: =F131-D131 -> 7 | F131: 264 | G131: =H131-F131 -> 13 | H131: 277 | I131: =ROUND(G131*$I$3,2) -> 48.54 | J131: =K131-H131 -> 9 | K131: 286 | L131: =ROUND(J131*$L$3,2) -> 37.39 | M131: =N131-K131 -> 7 | N131: 293 | O131: =ROUND(M131*$O$3,2) -> 44.7 | P131: =Q131-N131 -> 8 | Q131: 301 | R131: =ROUND(P131*$R$3,2) -> 22.96 | S131: =+T131-Q131 -> 10 | T131: 311 | U131: =ROUND(S131*$U$3,2) -> 29.8 | V131: =+W131-T131 -> 8 | W131: 319 | X131: =V131*$X$3 -> 23.8016
A132: DEPA-1201 | B132: 617 | C132: =D132-B132 -> 12 | D132: 629 | E132: =F132-D132 -> 20 | F132: 649 | G132: =H132-F132 -> 22 | H132: =496+175 -> 671 | I132: =ROUND(G132*$I$3,2) -> 82.15 | J132: =K132-H132 -> 20 | K132: =511+180 -> 691 | L132: =ROUND(J132*$L$3,2) -> 83.09 | M132: =N132-K132 -> 15 | N132: =522+184 -> 706 | O132: =ROUND(M132*$O$3,2) -> 95.78 | P132: =Q132-N132 -> 17 | Q132: =535+188 -> 723 | R132: =ROUND(P132*$R$3,2) -> 48.8 | S132: =+T132-Q132 -> 22 | T132: =552+193 -> 745 | U132: =ROUND(S132*$U$3,2) -> 65.56 | V132: =+W132-T132 -> 21 | W132: =567+199 -> 766 | X132: =V132*$X$3 -> 62.4792
A133: DEPA-1204 | B133: 113 | C133: =D133-B133 -> 7 | D133: 120 | E133: =F133-D133 -> 6 | F133: 126 | G133: =H133-F133 -> 7 | H133: 133 | I133: =ROUND(G133*$I$3,2) -> 26.14 | J133: =K133-H133 -> 6 | K133: 139 | L133: =ROUND(J133*$L$3,2) -> 24.93 | M133: =N133-K133 -> 5 | N133: 144 | O133: =ROUND(M133*$O$3,2) -> 31.93 | P133: =Q133-N133 -> 6 | Q133: 150 | R133: =ROUND(P133*$R$3,2) -> 17.22 | S133: =+T133-Q133 -> 9 | T133: 159 | U133: =ROUND(S133*$U$3,2) -> 26.82 | V133: =+W133-T133 -> 8 | W133: 167 | X133: =V133*$X$3 -> 23.8016 | Y133: Falta depa 1203
...

Sheet RESUMEN_mes
C3: Valores
A4: CODIGO | B4: PROPIETARIO(S) | C4: Suma de VALOR CUOTA | D4: Suma de AGUA CONSUMO | E4: Suma de SUMA
A5: PP-000 | B5: SIN IDENTIFICAR | C5: 171.3306 | D5: 0 | E5: 171.3306
A6: PP-001 | B6: AJK ASOCIADOS SAC | C6: 346.6529 | D6: 6.7269272 | E6: 353.37983
A7: PP-002 | B7: ALBAN MALACHE CHABELI | C7: 346.6529 | D7: 27.011841 | E7: 373.66474
A8: PP-003 | B8: RUIZ JAVIER ALEJANDRO | C8: 161.94649 | D8: 6.1854408 | E8: 168.13193
A9: PP-004 | B9: ALEXANDER STRAHLE JURGEN | C9: 346.6529 | D9: 17.8512 | E9: 364.5041
A10: PP-005 | B10: ALVA CUELLAR DUGLAS CONCEPCION | C10: 346.6529 | D10: 50.5784 | E10: 397.2313
A11: PP-006 | B11: ALVARADO BRINGAS MILUSKA CARLA | C11: 503.24306 | D11: 2.9752 | E11: 506.21826
A12: PP-007 | B12: ANTON ENICE | C12: 270.3657 | D12: 26.345396 | E12: 296.71109
A13: PP-008 | B13: APARCANA ROSADIO LUIS MIGUEL | C13: 238.2337 | D13: 5.9504 | E13: 244.1841
A14: PP-009 | B14: ASTO VARGAS HANS PIERRE | C14: 161.94649 | D14: 3.6862728 | E14: 165.63277
A15: PP-010 | B15: AVENDAÑO SILVA MIRLEY JESUS | C15: 76.287204 | D15: 0 | E15: 76.287204
A16: PP-011 | B16: AVILA JOEL ANTONIO | C16: 346.6529 | D16: 5.9504 | E16: 352.6033
... A208: PP-202 | B208: PALOMINO CRISTIAN | C208: 346.6529 | D208: 2.9752 | E208: 349.6281
A209: Total general | C209: 60462.665 | D209: 3879.3484 | E209: 64342.013

Sheet calculo
A1: CODIGO | B1: PROPIETARIO(S) | C1: PREDIO | D1: ÁREA TECHADA | E1: ÁREA OCUPADA | F1: % PARTICIPACIÓN | G1: VALOR CUOTA | H1: AGUA CONSUMO | I1: SUMA
A2: PP-000 | B2: SIN IDENTIFICAR | C2: E000 | D2: 0 | E2: 0 | F2: 0.00285 | G2: =pp_anual26*F2 -> 171.3306 | H2: =IFERROR(VLOOKUP(C2,consumo_agua!$A$7:$X$202,24,0),0) -> 0 | I2: =SUM(G2:H2) -> 171.3306
A3: PP-001 | B3: AJK ASOCIADOS SAC | C3: DEPA-1605 | D3: 78.95 | E3: 78.95 | F3: 0.0044974 | G3: =pp_anual26*F3 -> 270.3657 | H3: =IFERROR(VLOOKUP(C3,consumo_agua!$A$7:$X$202,24,0),0) -> 6.7269272 | I3: =SUM(G3:H3) -> 277.09263
A4: PP-001 | B4: AJK ASOCIADOS SAC | C4: ESTA-020 | D4: 0 | E4: 0 | F4: 0.001269 | G4: =pp_anual26*F4 -> 76.287204 | H4: =IFERROR(VLOOKUP(C4,consumo_agua!$A$7:$X$202,24,0),0) -> 0 | I4: =SUM(G4:H4) -> 76.287204
A5: PP-002 | B5: ALBAN MALACHE CHABELI | C5: DEPA-612 | D5: 74.6 | E5: 74.6 | F5: 0.0044974 | G5: =pp_anual26*F5 -> 270.3657 | H5: =IFERROR(VLOOKUP(C5,consumo_agua!$A$7:$X$202,24,0),0) -> 27.011841 | I5: =SUM(G5:H5) -> 297.37754
A6: PP-002 | B6: ALBAN MALACHE CHABELI | C6: ESTA-067 | D6: 0 | E6: 0 | F6: 0.001269 | G6: =pp_anual26*F6 -> 76.287204 | H6: =IFERROR(VLOOKUP(C6,consumo_agua!$A$7:$X$202,24,0),0) -> 0 | I6: =SUM(G6:H6) -> 76.287204
A7: PP-003 | B7: RUIZ JAVIER ALEJANDRO | C7: DEPA-811 | D7: 33 | E7: 33 | F7: 0.0026939 | G7: =pp_anual26*F7 -> 161.94649 | H7: =IFERROR(VLOOKUP(C7,consumo_agua!$A$7:$X$202,24,0),0) -> 6.1854408 | I7: =SUM(G7:H7) -> 168.13193
A8: PP-004 | B8: ALEXANDER STRAHLE JURGEN | C8: DEPA-902 | D8: 77.05 | E8: 77.05 | F8: 0.0044974 | G8: =pp_anual26*F8 -> 270.3657 | H8: =IFERROR(VLOOKUP(C8,consumo_agua!$A$7:$X$202,24,0),0) -> 17.8512 | I8: =SUM(G8:H8) -> 288.2169
A9: PP-004 | B9: ALEXANDER STRAHLE JURGEN | C9: ESTA-042 | D9: 0 | E9: 0 | F9: 0.001269 | G9: =pp_anual26*F9 -> 76.287204 | H9: =IFERROR(VLOOKUP(C9,consumo_agua!$A$7:$X$202,24,0),0) -> 0 | I9: =SUM(G9:H9) -> 76.287204
A10: PP-005 | B10: ALVA CUELLAR DUGLAS CONCEPCION | C10: DEPA-1205 | D10: 78.95 | E10: 78.95 | F10: 0.0044974 | G10: =pp_anual26*F10 -> 270.3657 | H10: =IFERROR(VLOOKUP(C10,consumo_agua!$A$7:$X$202,24,0),0) -> 50.5784 | I10: =SUM(G10:H10) -> 320.9441
A11: PP-005 | B11: ALVA CUELLAR DUGLAS CONCEPCION | C11: ESTA-077 | D11: 0 | E11: 0 | F11: 0.001269 | G11: =pp_anual26*F11 -> 76.287204 | H11: =IFERROR(VLOOKUP(C11,consumo_agua!$A$7:$X$202,24,0),0) -> 0 | I11: =SUM(G11:H11) -> 76.287204
A12: PP-006 | B12: ALVARADO BRINGAS MILUSKA CARLA | C12: DEPA-1001 | D12: 92.5 | E12: 92.5 | F12: 0.0056773 | G12: =pp_anual26*F12 -> 341.29657 | H12: =IFERROR(VLOOKUP(C12,consumo_agua!$A$7:$X$202,24,0),0) -> 2.9752 | I12: =SUM(G12:H12) -> 344.27177
A13: PP-006 | B13: ALVARADO BRINGAS MILUSKA CARLA | C13: ESTA-063 | D13: 0 | E13: 0 | F13: 0.0026939 | G13: =pp_anual26*F13 -> 161.94649 | H13: =IFERROR(VLOOKUP(C13,consumo_agua!$A$7:$X$202,24,0),0) -> 0 | I13: =SUM(G13:H13) -> 161.94649
... A383: PP-LAV | B383: LAVANDERIA PRONTOMATIK | C383: PP-LAV | D383: 0 | E383: 0 | F383: 0 | G383: =pp_anual26*F383 -> 0 | H383: =IFERROR(VLOOKUP(C383,consumo_agua!$A$7:$X$202,24,0),0) -> 142.8096 | I383: =SUM(G383:H383) -> 142.8096
D384: =SUM(D1:D383) -> 12835.37 | E384: =SUM(E1:E383) -> 12955.95 | F384: =SUM(F1:F383) -> 1.0057666 | G384: =SUM(G1:G383) -> 60462.665 | H384: =SUM(H1:H383) -> 3879.3484 | I384: =SUM(I1:I383) -> 64342.013

Sheet egresos
A1: Fecha | B1: Descripción operación | C1: Monto | D1: Operación - Número | E1: Referencia2
A2: 45895 | B2: IMPUESTO ITF | C2: -6.35 | D2: 00000000
A3: 45898 | B3: IMPUESTO ITF | C3: -0.1 | D3: 00000000
A4: 45899 | B4: ENVIO.EST.CTA | C4: -5.5 | D4: 00922526
A5: 45900 | B5: COM.MANTENIM | C5: -35 | D5: 00000000
A6: 45905 | B6: IMPUESTO ITF | C6: -0.05 | D6: 00000000
A7: 45909 | B7: EMIS. CHEQ DE GERENCIA | C7: -50016.5 | D7: 00216355
A8: 45909 | B8: IMPUESTO ITF | C8: -2.5 | D8: 00000000
A9: 45925 | B9: EMIS.CHEQ GEREN VENT | C9: -50014 | D9: 00073300
A10: 45925 | B10: COMISIONES CARTA ORDEN | C10: -60 | D10: 00070749
A11: 45930 | B11: COM.MANTENIM | C11: -35 | D11: 00000000
A12: 45930 | B12: ENVIO.EST.CTA | C12: -5.5 | D12: 00923700
A13: 45937 | B13: IMPUESTO ITF | C13: -0.05 | D13: 00000000
A14: 45945 | B14: A 194 35396121 0 | C14: -1724 | D14: 01284674 | E14: MANT CISTERNAS Y BOMBA
A15: 45945 | B15: TRANFERENCIA CCE | C15: -1084.3 | D15: 04022457
A16: 45945 | B16: A 192 74404443 0 | C16: -804 | D16: 01286577 | E16: PACIFIK MANT PRENVENTI
A17: 45945 | B17: A 191 74870101 0 | C17: -500 | D17: 01286103 | E17: REEMBOLSO GARANTIA DEP
A18: 45945 | B18: A 193 03842884 0 | C18: -430 | D18: 01286102 | E18: REEMBOLSO GARANTIA DEP
A19: 45945 | B19: A 191 7786938 0 | C19: -300 | D19: 01287551 | E19: SERVICIOS EXTRAS LIMPI
A20: 45945 | B20: IMPUESTO ITF | C20: -0.1 | D20: 00000000
A21: 45950 | B21: IMPUESTO ITF | C21: -0.05 | D21: 00000000
A22: 45953 | B22: IMPUESTO ITF | C22: -0.05 | D22: 00000000
A23: 45954 | B23: TRANFERENCIA CCE | C23: -24430.3 | D23: 04012974
A24: 45954 | B24: A 191 2097589 0 | C24: -1374 | D24: 01162648 | E24: material limpieza paci
A25: 45954 | B25: A 193 04699499 0 | C25: -1000 | D25: 01163128 | E25: Audit gestion dos anos
A26: 45954 | B26: A 191 97211880 0 | C26: -580 | D26: 01161183 | E26: RG depa 1212 lounge an
A27: 45954 | B27: A 191 04291231 0 | C27: -500 | D27: 01160717 | E27: reembolso garantia DEP
A28: 45954 | B28: A 191 39132335 0 | C28: -500 | D28: 01160225 | E28: RG depa 207 lounge 251
A29: 45954 | B29: A 191 01775351 0 | C29: -500 | D29: 01161184 | E29: RG depa 1002 lounge 25
A30: 45954 | B30: A 193 35382222 0 | C30: -450 | D30: 01163129 | E30: REEMBOLSO GARANTIA DEP
A31: 45954 | B31: A 191 29719140 0 | C31: -430 | D31: 01162144 | E31: reembolso garantia DEP
A32: 45954 | B32: A 192 97940244 0 | C32: -330 | D32: 01161182 | E32: reembolso garantia dep
A33: 45954 | B33: A 191 08348364 0 | C33: -300 | D33: 01161679 | E33: Honorarios agosto y se
A34: 45954 | B34: A 193 76088550 0 | C34: -167.9 | D34: 01162647 | E34: reembolso internet mov
A35: 45954 | B35: A 193 17476343 0 | C35: -100 | D35: 01161678 | E35: RG depa 312 arcade 251
... A37: 45954 | B37: A 193 04699499 0 | C37: -99.9 | D37: 01161185 | E37: Internet Pacifik 20250
A38: 45954 | B38: IMPUESTO ITF | C38: -1.3 | D38: 00000000
A39: 45958 | B39: A 194 2636555 0 | C39: -2080 | D39: 01111134 | E39: 50 LUMINARIAS CON SENS
A40: 45958 | B40: A 194 2636555 0 | C40: -2080 | D40: 01172874 | E40: SALDO 50 LUMINARIAS CO
A41: 45958 | B41: A 191 2367445 0 | C41: -690 | D41: 01108214 | E41: ANTICIPO 40 INSTALACIO
...

Sheet tablas
A1: anexo
A2: 2025-01
A3: 2025-02
A4: 2025-03
A5: 2025-04
A6: 2025-05
A7: 2025-06
A8: 2025-07
A9: 2025-08
A10: 2025-09
A11: 2025-10
A12: 2025-11
... A20: sin identificar

Sheet codigos
A1: CODIGO | B1: PROPIETARIO(S) | C1: propiedad
A2: PP-000 | B2: SIN IDENTIFICAR | C2: E000
A3: PP-001 | B3: AJK ASOCIADOS SAC | C3: DEPA-1605
A4: PP-002 | B4: ALBAN MALACHE CHABELI | C4: DEPA-612
A5: PP-003 | B5: RUIZ JAVIER ALEJANDRO | C5: DEPA-811
A6: PP-004 | B6: ALEXANDER STRAHLE JURGEN | C6: DEPA-902
A7: PP-005 | B7: ALVA CUELLAR DUGLAS CONCEPCION | C7: DEPA-1205
A8: PP-006 | B8: ALVARADO BRINGAS MILUSKA CARLA | C8: DEPA-1001
A9: PP-007 | B9: ANTON ENICE | C9: DEPA-610
A10: PP-008 | B10: APARCANA ROSADIO LUIS MIGUEL | C10: DEPA-606
A11: PP-009 | B11: ASTO VARGAS HANS PIERRE | C11: DEPA-1311
A12: PP-010 | B12: AVENDAÑO SILVA MIRLEY JESUS | C12: ESTA-087
... A205: PP-LAV | B205: LAVANDERIA PRONTOMATIK | C205: PP-LAV

Sheet ingresos
A1: mes | B1: fecha | C1: glosa | D1: valor soles | E1: operación nro. | F1: codigo | G1: anexo | H1: detalle-referencia
A2: 8 | B2: 45870 | C2: varios | D2: 0 | E2: 9999999 | F2: PP-000 | H2: GENERICO
A3: 8 | B3: 45895 | C3: TRANSF.BCO.INTERBANK | D3: 306.42 | E3: 02130246 | F3: PP-017 | G3: 2025-08 | H3: BLAS-OLIVER-LIDIA | I3: 5
A4: 8 | B4: 45895 | C4: TRAN.CTAS.TERC.BM | D4: 580 | E4: 01030013 | G4: lounge | H4: BUSTAMANTE RUIZ EDUARDO CARLOS | I4: 6
A5: 8 | B5: 45895 | C5: TRAN.CTAS.TERC.BM | D5: 333.9 | E5: 01528693 | F5: PP-022 | G5: 2025-07 | H5: CARDENAS MORIANO HEVELYNE HILDA | I5: 5
A6: 8 | B6: 45895 | C6: TRAN.CTAS.TERC.BM | D6: 411.38 | E6: 04244321 | F6: PP-128 | G6: 2025-08 | H6: CELI GUTIERREZ DIANA KARINA | I6: 7
A7: 8 | B7: 45895 | C7: TRAN.CTAS.TERC.BM | D7: 275.58 | E7: 04079146 | F7: PP-090 | G7: 2025-08 | H7: CUBA REYES ANGIE CONSUELO LESLIE | I7: 5
A8: 8 | B8: 45895 | C8: TRAN.CTAS.TERC.BM | D8: 168.8 | E8: 01403678 | F8: PP-082 | G8: 2025-08 | H8: HUERTA HUERTA CARLA ALESSANDRA | I8: 5
A9: 8 | B9: 45895 | C9: TRANSF.BCO.BBVA | D9: 23.37 | E9: 02276178 | F9: PP-039 | G9: 2025-08 | H9: JOSE AUGUSTO CANDELA ROJAS | I9: 5
A10: 8 | B10: 45895 | C10: TRANSF.BCO.BBVA | D10: 372.01 | E10: 02271919 | F10: PP-190 | G10: 2025-08 | H10: MARIA GISELLA YOUNG GUERRERO | I10: 5
A11: 8 | B11: 45895 | C11: TRAN.CTAS.TERC.BM | D11: 301.72 | E11: 01860628 | F11: PP-108 | G11: 2025-08 | H11: MENDOZA BAZAN SILVIA VERONICA | I11: 4
A12: 8 | B12: 45895 | C12: TRAN.CTAS.TERC.BM | D12: 455.51 | E12: 03214653 | F12: PP-119 | G12: 2025-08 | H12: NUNEZ ESTRADA YULY CRISTINA | I12: 7
A13: 8 | B13: 45895 | C13: TRAN.CTAS.TERC.HK | D13: 168.8 | E13: 06046753 | F13: PP-122 | G13: 2025-08 | H13: OLIVARES SAAVEDRA JAIME ALBERTO | I13: 5
A14: 8 | B14: 45895 | C14: TRANSF.BCO.INTERBANK | D14: 404.47 | E14: 02185017 | F14: PP-129 | G14: 2025-08 | H14: ORE-ROSARIO-CRISTOPHER | I14: 6
A15: 8 | B15: 45895 | C15: TRAN.CTAS.TERC.BM | D15: 380.04 | E15: 04046820 | F15: PP-145 | G15: 2025-08 | H15: REGALADO SANTANA MARIA CELINDA | I15: 6
A16: 8 | B16: 45895 | C16: ENTREGA C/CHEQUES FUE | D16: 127565.13 | E16: 00788858 | F16: PACIFIK | G16: sin identificar | H16: VENTANILLA | I16: 3
... A23: 8 | B23: 45896 | C23: TRAN.CTAS.TERC.BM | D23: 261.5 | E23: 00157192 | F23: PP-094 | G23: 2025-08 | H23: MEJIA TURRIATE DEBORA DICK | I23: 5
A24: 8 | B24: 45896 | C24: TRAN.CTAS.TERC.BM | D24: 580 | E24: 00589497 | G24: lounge | H24: MILUSKA CRIS TAPIA CASARETTO | I24: 6
A25: 8 | B25: 45896 | C25: TRAN.CTAS.TERC.BM | D25: 265.23 | E25: 00669135 | F25: PP-046 | G25: 2025-08 | H25: MILUSKA CRIS TAPIA CASARETTO | I25: 6
A26: 8 | B26: 45896 | C26: TRANSF.BCO.INTERBANK | D26: 507.9 | E26: 02556593 | F26: PP-137 | G26: 2025-08 | H26: RAMOS-REQUEJO-MABEL | I26: 6
A27: 8 | B27: 45896 | C27: TRAN.CTAS.TERC.BM | D27: 379.48 | E27: 00603438 | F27: PP-045 | G27: 2025-08 | H27: RUIZ SANDOVAL FLOR DE MARIA | I27: 5
A28: 8 | B28: 45896 | C28: TRAN.CTAS.TERC.BM | D28: 175.82 | E28: 05034305 | F28: PP-081 | G28: 2025-08 | H28: TIPON GALVIS MICHAEL | I28: 5
A29: 8 | B29: 45896 | C29: TRAN.CTAS.TERC.BM | D29: 195.06 | E29: 03392234 | F29: PP-174 | G29: 2025-08 | H29: VALDEZ CADENILLAS AGUSTIN | I29: 8
A30: 8 | B30: 45896 | C30: TRAN.CTAS.TERC.BM | D30: 165.07 | E30: 01737357 | F30: PP-175 | G30: 2025-08 | H30: VALDIVIA OBANDO OSCAR EDMUNDO FRANCISCO | I30: 2
A31: 8 | B31: 45896 | C31: DEPOSITO AG 971093 | D31: 468 | E31: 00048102 | F31: PP-186 | G31: 2025-08 | I31: 5
A32: 8 | B32: 45897 | C32: DEPOSITO AG 981945 | D32: 429.4 | E32: 00090790 | F32: PP-058 | G32: 2025-08 | H32: CISNEROS CAHUANA JUANA CLENIA | I32: 5
A33: 8 | B33: 45897 | C33: TRAN.CTAS.TERC.BM | D33: 374.56 | E33: 03212730 | F33: PP-040 | G33: 2025-08 | H33: CORDERO VILCA PEDRO LUIS | I33: 7
A34: 8 | B34: 45897 | C34: TRANSF.BCO.SCOTIABANK | D34: 181.74 | E34: 02868748 | F34: PP-009 | G34: 2025-08 | H34: DIEGO SEGURA MENDEZ | I34: 5
A35: 8 | B35: 45897 | C35: TRANSF.BCO.INTERBANK | D35: 316.65 | E35: 02132541 | F35: PP-142 | G35: 2025-08 | H35: GARCIA-SUAREZ-CARLOS | I35: 5
A36: 8 | B36: 45897 | C36: TRAN.CTAS.TERC.BM | D36: 243.49 | E36: 01430615 | F36: PP-184 | G36: 2025-08 | H36: GUERRERO GUERRERO BENNER ROLAN | I36: 5
A37: 8 | B37: 45897 | C37: TRAN.CTAS.TERC.BM | D37: 202.41 | E37: 04731144 | F37: PP-158 | G37: 2025-08 | H37: MEDINA SARMIENTO JAVIER | I37: 4
A38: 8 | B38: 45897 | C38: TRAN.CTAS.TERC.BM | D38: 312.92 | E38: 00668414 | F38: PP-068 | G38: 2025-08 | H38: MONICA JULIE GUERRERO ABARCA | I38: 6
A39: 8 | B39: 45897 | C39: TRANSF.BCO.INTERBANK | D39: 175.66 | E39: 02267630 | F39: PP-102 | G39: 2025-08 | H39: MORALES-DURAND-DE-DURAN-ZANDRA | I39: 7
A40: 8 | B40: 45897 | C40: TRAN.CTAS.TERC.BM | D40: 372.01 | E40: 01569667 | F40: PP-118 | G40: 2025-08 | H40: NEIRA UN JAN MILAGROS ANDREA | I40: 7
A41: 8 | B41: 45897 | C41: TRAN.CTAS.TERC.HK | D41: 77.76 | E41: 06017738 | F41: PP-123 | G41: 2025-07 | H41: ORELLANA VARGAS CARMEN ROSA | I41: 10
A42: 8 | B42: 45898 | C42: DE BERTOLOTTO INVESTME | D42: 2056.59 | E42: 02050826 | F42: PP-016 | G42: 2025-08 | H42: BERTOLOTTO INVESTMENTS S.A.C. | I42: 3
A43: 8 | B43: 45898 | C43: TRAN.CTAS.TERC.BM | D43: 389.76 | E43: 04758347 | F43: PP-044 | G43: 2025-07 | H43: DE-LA-CRUZ DELGADO WALTER | I43: 5
... A58: 8 | B58: 45899 | C58: TRANSF.BCO.INTERBANK | D58: 191.21 | E58: 02477847 | F58: PP-035 | G58: 2025-08 | H58: CHAVEZ-TAGLE-SISLEY | I58: 5
A59: 8 | B59: 45899 | C59: TRANSF.BCO.SCOTIABANK | D59: 30 | E59: 02575512 | G59: cine | H59: EDWARD SANDOVAL AMASIFUEN | I59: 6
A60: 8 | B60: 45899 | C60: TRAN.CTAS.TERC.BM | D60: 394.41 | E60: 02466805 | F60: PP-181 | G60: 2025-08 | H60: FIGUEROA MARQUEZ ELIZABETH JANETH | I60: 5
...

Sheet cuotas_emitidas
A1: CODIGO | B1: PROPIETARIO(S) | C1: propiedad | D1: 2023 | E1: 2024 | F1: 2025-01 | G1: 2025-02 | H1: 2025-03 | I1: 2025-04 | J1: 2025-05 | K1: 2025-06 | L1: 2025-07 | M1: 2025-08 | N1: 2025-09 | O1: 2025-10 | P1: 2025-11 | Q1: 2025-12 | R1: acumulado
A2: PP-000 | B2: SIN IDENTIFICAR | C2: E000 | M2: 174.63 | N2: 180.84 | O2: 180.84 | P2: 180.84 | Q2: 180.84 | R2: =SUM(D2:Q2) -> 897.99
A3: PP-001 | B3: AJK ASOCIADOS SAC | C3: DEPA-1605 | F3: 0 | G3: 0 | H3: 0 | I3: 0 | J3: 0 | K3: 385.31 | L3: 382.13 | M3: 368.11 | N3: 378.78 | O3: 377.16 | P3: 370.23 | Q3: 377.02 | R3: =SUM(D3:Q3) -> 2638.74
A4: PP-002 | B4: ALBAN MALACHE CHABELI | C4: DEPA-612 | M4: 392.7 | N4: 404.17 | O4: 408.64 | P4: 387.14 | Q4: 395.44 | R4: =SUM(D4:Q4) -> 1988.09
A5: PP-003 | B5: RUIZ JAVIER ALEJANDRO | C5: DEPA-811 | M5: 173.01 | N5: 179.66 | O5: 178.54 | P5: 172.94 | Q5: 179.63 | R5: =SUM(D5:Q5) -> 883.78
A6: PP-004 | B6: ALEXANDER STRAHLE JURGEN | C6: DEPA-902 | M6: 379.5 | N6: 386.65 | O6: 385.04 | P6: 380.23 | Q6: 383.76 | R6: =SUM(D6:Q6) -> 1915.18
A7: PP-005 | B7: ALVA CUELLAR DUGLAS CONCEPCION | C7: DEPA-1205 | M7: 386.94 | N7: 419.89 | O7: 423.35 | P7: 403.2 | Q7: 410.58 | R7: =SUM(D7:Q7) -> 2043.96
A8: PP-006 | B8: ALVARADO BRINGAS MILUSKA CARLA | C8: DEPA-1001 | M8: 516.68 | N8: 531.16 | O8: 531.16 | P8: 531.16 | Q8: 534.14 | R8: =SUM(D8:Q8) -> 2644.3
A9: PP-007 | B9: ANTON ENICE | C9: DEPA-610 | F9: 0 | G9: 0 | H9: 0 | I9: 0 | J9: 0 | K9: 0 | L9: 324.29 | M9: 312.03 | N9: 327.24 | O9: 324.7 | P9: 306.74 | Q9: 318.57 | R9: =SUM(D9:Q9) -> 1913.57
A10: PP-008 | B10: APARCANA ROSADIO LUIS MIGUEL | C10: DEPA-606 | M10: 242.83 | N10: 255.6 | O10: 257.84 | P10: 254.32 | Q10: 251.45 | R10: =SUM(D10:Q10) -> 1262.04
A11: PP-009 | B11: ASTO VARGAS HANS PIERRE | C11: DEPA-1311 | M11: 181.74 | N11: 183.67 | O11: 183.15 | P11: 176.23 | Q11: 182.14 | R11: =SUM(D11:Q11) -> 906.93
A12: PP-010 | B12: AVENDAÑO SILVA MIRLEY JESUS | C12: ESTA-087 | F12: 0 | G12: 0 | H12: 0 | I12: 0 | J12: 0 | K12: 0 | L12: 80.52 | M12: 77.76 | N12: 80.52 | O12: 80.52 | P12: 80.52 | Q12: 80.52 | R12: =SUM(D12:Q12) -> 480.36
A13: PP-011 | B13: AVILA JOEL ANTONIO | C13: DEPA-804 | F13: 0 | G13: 0 | H13: 0 | I13: 0 | J13: 0 | K13: 0 | L13: 377.49 | M13: 357.07 | N13: 374.19 | O13: 365.88 | P13: 368.75 | Q13: 368.86 | R13: =SUM(D13:Q13) -> 2212.24
A14: PP-012 | B14: AYAQUE LARICO ISAAC ALFREDO | C14: DEPA-1602 | M14: 357.07 | N14: 370.03 | O14: 365.88 | P14: 371.62 | Q14: 365.88 | R14: =SUM(D14:Q14) -> 1830.48
A15: PP-013 | B15: BADA CARPIO OSCAR | C15: DEPA-101 | M15: 641.05 | N15: 654.98 | O15: 674.36 | P15: 613.96 | Q15: 624.98 | R15: =SUM(D15:Q15) -> 3209.33
A16: PP-014 | B16: HENDRICK OSCAR / HENDRICKLUISA | C16: DEPA-1101 | M16: 425.63 | N16: 440.75 | O16: 440.75 | P16: 440.75 | Q16: 440.75 | R16: =SUM(D16:Q16) -> 2188.63
A17: PP-015 | B17: BENITES CERNA CARLOS ENRIQUE | C17: DEPA-1006 | M17: 445.24 | N17: 447.3 | O17: 447.92 | P17: 441.54 | Q17: 440.26 | R17: =SUM(D17:Q17) -> 2222.26
A18: PP-016 | B18: BERTOLOTTO INVESTMENTS S.A.C | C18: DEPA-1703 | M18: 2056.59 | N18: 1268.22 | O18: 1264.37 | P18: 1099.17 | Q18: 1096.52 | R18: =SUM(D18:Q18) -> 6784.87
A19: PP-017 | B19: BLAS OLIVER LIDIA ROSALVA | C19: DEPA-1609 | M19: 306.42 | N19: 320.47 | O19: 332.24 | P19: 306.34 | Q19: 313.51 | R19: =SUM(D19:Q19) -> 1578.98
A20: PP-018 | B20: CALDERON MINCHOLA JUAN CARLOS | C20: DEPA-1401 | F20: 0 | G20: 0 | H20: 0 | I20: 0 | J20: 0 | K20: 456.23 | L20: 456.23 | M20: 445 | N20: 453.21 | O20: 453.52 | P20: 449.36 | Q20: 449.69 | R20: =SUM(D20:Q20) -> 3163.24
A21: PP-019 | B21: CANCINO APAZA MARYLIN MARYBEL | C21: DEPA-1504 | F21: 0 | G21: 0 | H21: 0 | I21: 0 | J21: 0 | K21: 369.75 | L21: 377.49 | M21: 360.81 | N21: 374.19 | O21: 378.65 | P21: 374.49 | Q21: 365.88 | R21: =SUM(D21:Q21) -> 2601.26
A22: PP-020 | B22: CANEDO TAPIA MANUEL HERNAN | C22: DEPA-1710 | M22: 411.66 | N22: 434.92 | O22: 434.56 | P22: 403.19 | Q22: 418.32 | R22: =SUM(D22:Q22) -> 2102.65
A23: PP-021 | B23: CAO DACHAO | C23: DEPA-1310 | M23: 365.78 | N23: 385.43 | O23: 382.69 | P23: 374.78 | Q23: 382.97 | R23: =SUM(D23:Q23) -> 1891.65
A24: PP-022 | B24: CARDENAS MORIANO HEVELYNE HILDA | C24: DEPA-1607 | F24: 0 | G24: 0 | H24: 0 | I24: 0 | J24: 0 | K24: 0 | L24: 333.9 | M24: 342.91 | N24: 341.92 | O24: 346.99 | P24: 331.64 | Q24: 332.52 | R24: =SUM(D24:Q24) -> 2029.88
A25: PP-023 | B25: CARDENAS MORIANO WOLFGAN ANGEL | C25: DEPA-1107 | F25: 0 | G25: 0 | H25: 0 | I25: 0 | J25: 0 | K25: 0 | L25: 328.03 | M25: 327.97 | N25: 341.92 | O25: 327.84 | P25: 323.03 | Q25: 335.5 | R25: =SUM(D25:Q25) -> 1984.29
A26: PP-024 | B26: CARMONA DIAZ MERY | C26: DEPA-1201 | M26: 950.48 | N26: 982.26 | O26: 994.95 | P26: 947.97 | Q26: 964.73 | R26: =SUM(D26:Q26) -> 4840.39
A27: PP-025 | B27: CARRASCO BEAS ALFREDO EDILBERTO | C27: DEPA-1306 | M27: 242.83 | N27: 251.45 | O27: 251.45 | P27: 251.45 | Q27: 251.45 | R27: =SUM(D27:Q27) -> 1248.63
A28: PP-026 | B28: CARRILLO GALLO EDSON | C28: DEPA-611 | F28: 0 | G28: 0 | H28: 0 | I28: 0 | J28: 0 | K28: 0 | L28: 180.18 | M28: 187.7 | N28: 197.87 | O28: 208.18 | P28: 188.79 | Q28: 194.25 | R28: =SUM(D28:Q28) -> 1156.97
A29: PP-027 | B29: CARRILLO PINEDA FERNANDO | C29: ESTA-140 | M29: 77.76 | N29: 80.52 | O29: 80.52 | P29: 80.52 | Q29: 80.52 | R29: =SUM(D29:Q29) -> 399.84
A30: PP-028 | B30: CASAS JOSE | C30: DEPA-1002 | M30: 401.88 | N30: 419.89 | O30: 416.96 | P30: 400.32 | Q30: 404.62 | R30: =SUM(D30:Q30) -> 2043.67
A31: PP-029 | B31: CASTILLA PEREZ CARMELA FERMINA | C31: DEPA-1204 | F31: 0 | G31: 0 | H31: 0 | I31: 0 | J31: 385.23 | K31: 401 | L31: 392.97 | M31: 379.48 | N31: 390.81 | O31: 397.81 | P31: 383.1 | Q31: 392.7 | R31: =SUM(D31:Q31) -> 3123.1
A32: PP-030 | B32: CASTRO ALMEIDA RAUL ARMANDO | C32: DEPA-1403 | F32: 0 | G32: 0 | H32: 0 | I32: 0 | J32: 0 | K32: 0 | L32: 396.84 | M32: 394.42 | N32: 403.27 | O32: 410.58 | P32: 388.84 | Q32: 389.72 | R32: =SUM(D32:Q32) -> 2383.67
A33: PP-031 | B33: CASTRO BARRERA ANITA MARITZA | C33: DEPA-407 | M33: 401.88 | N33: 415.74 | O33: 429.74 | P33: 394.58 | Q33: 398.66 | R33: =SUM(D33:Q33) -> 2040.6
A34: PP-032 | B34: SOLARI ATOCHE MARIA CECILIA | C34: DEPA-907 | F34: 0 | G34: 0 | H34: 0 | I34: 0 | J34: 0 | K34: 358.89 | L34: 324.06 | M34: 275.58 | N34: 285.36 | O34: 298.13 | P34: 285.36 | Q34: 306.22 | R34: =SUM(D34:Q34) -> 2133.6
A35: PP-033 | B35: CHAFLOQUE MORENO ALEXIS JHONNY | C35: DEPA-1312 | F35: 0 | G35: 0 | H35: 0 | I35: 0 | J35: 0 | K35: 0 | L35: 324.06 | M35: 312.92 | N35: 322.75 | O35: 330.06 | P35: 308.32 | Q35: 321.12 | R35: =SUM(D35:Q35) -> 1919.23
A36: PP-034 | B36: CHAVEZ JULCAHUANCA VANESSA | C36: DEPA-1111 | F36: 0 | G36: 0 | H36: 0 | I36: 0 | J36: 197.44 | K36: 195.43 | L36: 198.02 | M36: 189.65 | N36: 196.1 | O36: 196.68 | P36: 185.59 | Q36: 190.56 | R36: =SUM(D36:Q36) -> 1549.47
A37: PP-035 | B37: CHAVEZ TAGLE SISLEY | C37: DEPA-609 | F37: 0 | G37: 0 | H37: 0 | I37: 0 | J37: 0 | K37: 0 | L37: 182.54 | M37: 191.21 | N37: 191.7 | O37: 202.86 | P37: 185.28 | Q37: 188.81 | R37: =SUM(D37:Q37) -> 1142.4
A38: PP-036 | B38: CHAVEZ MYLADY | C38: DEPA-510 | F38: 0 | G38: 0 | H38: 0 | I38: 0 | J38: 0 | K38: 0 | L38: 307.88 | M38: 275.58 | N38: 335.45 | O38: 313.69 | P38: 300.13 | Q38: 303.3 | R38: =SUM(D38:Q38) -> 1836.03
A39: PP-037 | B39: CHIA ALEGRE JORGE WILLIAMS | C39: DEPA-202 | M39: 297.98 | N39: 297.83 | O39: 310.9 | P39: 296.84 | Q39: 300.26 | R39: =SUM(D39:Q39) -> 1503.81
A40: PP-038 | B40: CHIROQUE FLOR LOZANO | C40: DEPA-1011 | M40: 172.12 | N40: 184.66 | O40: 186.24 | P40: 178.33 | Q40: 182.5 | R40: =SUM(D40:Q40) -> 903.85
...

Sheet saldos
A1: EDIFICIO MULTIFAMILIAR "PACIFIK OCEAN TOWER"
A2: Av. Bertolotto Negro 850 - San Miguel
A3: 20614642247
A4: Listado de morosos al 31/12/2025
A6: CODIGO | B6: PROPIETARIO(S) | C6: propiedad | D6: 2023 | E6: 2024 | F6: 2025-01 | G6: 2025-02 | H6: 2025-03 | I6: 2025-04 | J6: 2025-05 | K6: 2025-06 | L6: 2025-07 | M6: 2025-08 | N6: 2025-09 | O6: 2025-10 | P6: 2025-11 | Q6: 2025-12 | R6: acumulado | T6: ULTIMO MES DIC-2025 | U6: MESES ANTERIORES
A7: PP-000 | B7: SIN IDENTIFICAR | C7: E000 | D7: =cuotas_emitidas!D2-SUMIFS(ingresos!$D:$D,ingresos!$F:$F,saldos!$A7,ingresos!$G:$G,saldos!D$6) -> 0 | E7: =cuotas_emitidas!E2-SUMIFS(ingresos!$D:$D,ingresos!$F:$F,saldos!$A7,ingresos!$G:$G,saldos!E$6) -> 0 | F7: =cuotas_emitidas!F2-SUMIFS(ingresos!$D:$D,ingresos!$F:$F,saldos!$A7,ingresos!$G:$G,saldos!F$6) -> 0 | G7: =cuotas_emitidas!G2-SUMIFS(ingresos!$D:$D,ingresos!$F:$F,saldos!$A7,ingresos!$G:$G,saldos!G$6) -> 0 | H7: =cuotas_emitidas!H2-SUMIFS(ingresos!$D:$D,ingresos!$F:$F,saldos!$A7,ingresos!$G:$G,saldos!H$6) -> 0 | I7: =cuotas_emitidas!I2-SUMIFS(ingresos!$D:$D,ingresos!$F:$F,saldos!$A7,ingresos!$G:$G,saldos!I$6) -> 0 | J7: =cuotas_emitidas!J2-SUMIFS(ingresos!$D:$D,ingresos!$F:$F,saldos!$A7,ingresos!$G:$G,saldos!J$6) -> 0 | K7: =cuotas_emitidas!K2-SUMIFS(ingresos!$D:$D,ingresos!$F:$F,saldos!$A7,ingresos!$G:$G,saldos!K$6) -> 0 | ... Q7: =cuotas_emitidas!Q2-SUMIFS(ingresos!$D:$D,ingresos!$F:$F,saldos!$A7,ingresos!$G:$G,saldos!Q$6) -> 180.84 | R7: =SUM(D7:Q7) -> 897.99 | T7: =Q7 -> 180.84 | U7: =R7-T7 -> 717.15
A8: PP-001 | B8: AJK ASOCIADOS SAC | C8: DEPA-1605 | D8: =cuotas_emitidas!D3-SUMIFS(ingresos!$D:$D,ingresos!$F:$F,saldos!$A8,ingresos!$G:$G,saldos!D$6) -> 0 | E8: =cuotas_emitidas!E3-SUMIFS(ingresos!$D:$D,ingresos!$F:$F,saldos!$A8,ingresos!$G:$G,saldos!E$6) -> 0 | F8: =cuotas_emitidas!F3-SUMIFS(ingresos!$D:$D,ingresos!$F:$F,saldos!$A8,ingresos!$G:$G,saldos!F$6) -> 0 | G8: =cuotas_emitidas!G3-SUMIFS(ingresos!$D:$D,ingresos!$F:$F,saldos!$A8,ingresos!$G:$G,saldos!G$6) -> 0 | H8: =cuotas_emitidas!H3-SUMIFS(ingresos!$D:$D,ingresos!$F:$F,saldos!$A8,ingresos!$G:$G,saldos!H$6) -> 0 | I8: =cuotas_emitidas!I3-SUMIFS(ingresos!$D:$D,ingresos!$F:$F,saldos!$A8,ingresos!$G:$G,saldos!I$6) -> 0 | J8: =cuotas_emitidas!J3-SUMIFS(ingresos!$D:$D,ingresos!$F:$F,saldos!$A8,ingresos!$G:$G,saldos!J$6) -> 0 | K8: =cuotas_emitidas!K3-SUMIFS(ingresos!$D:$D,ingresos!$F:$F,saldos!$A8,ingresos!$G:$G,saldos!K$6) -> 0 | ... Q8: =cuotas_emitidas!Q3-SUMIFS(ingresos!$D:$D,ingresos!$F:$F,saldos!$A8,ingresos!$G:$G,saldos!Q$6) -> 377.02 | R8: =SUM(D8:Q8) -> 377.02 | T8: =Q8 -> 377.02 | U8: =R8-T8 -> 0
A9: PP-002 | B9: ALBAN MALACHE CHABELI | C9: DEPA-612 | D9: =cuotas_emitidas!D4-SUMIFS(ingresos!$D:$D,ingresos!$F:$F,saldos!$A9,ingresos!$G:$G,saldos!D$6) -> 0 | E9: =cuotas_emitidas!E4-SUMIFS(ingresos!$D:$D,ingresos!$F:$F,saldos!$A9,ingresos!$G:$G,saldos!E$6) -> 0 | F9: =cuotas_emitidas!F4-SUMIFS(ingresos!$D:$D,ingresos!$F:$F,saldos!$A9,ingresos!$G:$G,saldos!F$6) -> 0 | G9: =cuotas_emitidas!G4-SUMIFS(ingresos!$D:$D,ingresos!$F:$F,saldos!$A9,ingresos!$G:$G,saldos!G$6) -> 0 | H9: =cuotas_emitidas!H4-SUMIFS(ingresos!$D:$D,ingresos!$F:$F,saldos!$A9,ingresos!$G:$G,saldos!H$6) -> 0 | I9: =cuotas_emitidas!I4-SUMIFS(ingresos!$D:$D,ingresos!$F:$F,saldos!$A9,ingresos!$G:$G,saldos!I$6) -> 0 | J9: =cuotas_emitidas!J4-SUMIFS(ingresos!$D:$D,ingresos!$F:$F,saldos!$A9,ingresos!$G:$G,saldos!J$6) -> 0 | K9: =cuotas_emitidas!K4-SUMIFS(ingresos!$D:$D,ingresos!$F:$F,saldos!$A9,ingresos!$G:$G,saldos!K$6) -> 0 | ... Q9: =cuotas_emitidas!Q4-SUMIFS(ingresos!$D:$D,ingresos!$F:$F,saldos!$A9,ingresos!$G:$G,saldos!Q$6) -> 395.44 | R9: =SUM(D9:Q9) -> 395.44 | T9: =Q9 -> 395.44 | U9: =R9-T9 -> 0
A10: PP-003 | B10: RUIZ JAVIER ALEJANDRO | C10: DEPA-811 | D10: =cuotas_emitidas!D5-SUMIFS(ingresos!$D:$D,ingresos!$F:$F,saldos!$A10,ingresos!$G:$G,saldos!D$6) -> 0 | E10: =cuotas_emitidas!E5-SUMIFS(ingresos!$D:$D,ingresos!$F:$F,saldos!$A10,ingresos!$G:$G,saldos!E$6) -> 0 | F10: =cuotas_emitidas!F5-SUMIFS(ingresos!$D:$D,ingresos!$F:$F,saldos!$A10,ingresos!$G:$G,saldos!F$6) -> 0 | G10: =cuotas_emitidas!G5-SUMIFS(ingresos!$D:$D,ingresos!$F:$F,saldos!$A10,ingresos!$G:$G,saldos!G$6) -> 0 | H10: =cuotas_emitidas!H5-SUMIFS(ingresos!$D:$D,ingresos!$F:$F,saldos!$A10,ingresos!$G:$G,saldos!H$6) -> 0 | I10: =cuotas_emitidas!I5-SUMIFS(ingresos!$D:$D,ingresos!$F:$F,saldos!$A10,ingresos!$G:$G,saldos!I$6) -> 0 | J10: =cuotas_emitidas!J5-SUMIFS(ingresos!$D:$D,ingresos!$F:$F,saldos!$A10,ingresos!$G:$G,saldos!J$6) -> 0 | K10: =cuotas_emitidas!K5-SUMIFS(ingresos!$D:$D,ingresos!$F:$F,saldos!$A10,ingresos!$G:$G,saldos!K$6) -> 0 | ... Q10: =cuotas_emitidas!Q5-SUMIFS(ingresos!$D:$D,ingresos!$F:$F,saldos!$A10,ingresos!$G:$G,saldos!Q$6) -> 179.63 | R10: =SUM(D10:Q10) -> 179.63 | T10: =Q10 -> 179.63 | U10: =R10-T10 -> 0
A11: PP-004 | B11: ALEXANDER STRAHLE JURGEN | C11: DEPA-902 | D11: =cuotas_emitidas!D6-SUMIFS(ingresos!$D:$D,ingresos!$F:$F,saldos!$A11,ingresos!$G:$G,saldos!D$6) -> 0 | E11: =cuotas_emitidas!E6-SUMIFS(ingresos!$D:$D,ingresos!$F:$F,saldos!$A11,ingresos!$G:$G,saldos!E$6) -> 0 | F11: =cuotas_emitidas!F6-SUMIFS(ingresos!$D:$D,ingresos!$F:$F,saldos!$A11,ingresos!$G:$G,saldos!F$6) -> 0 | G11: =cuotas_emitidas!G6-SUMIFS(ingresos!$D:$D,ingresos!$F:$F,saldos!$A11,ingresos!$G:$G,saldos!G$6) -> 0 | H11: =cuotas_emitidas!H6-SUMIFS(ingresos!$D:$D,ingresos!$F:$F,saldos!$A11,ingresos!$G:$G,saldos!H$6) -> 0 | I11: =cuotas_emitidas!I6-SUMIFS(ingresos!$D:$D,ingresos!$F:$F,saldos!$A11,ingresos!$G:$G,saldos!I$6) -> 0 | J11: =cuotas_emitidas!J6-SUMIFS(ingresos!$D:$D,ingresos!$F:$F,saldos!$A11,ingresos!$G:$G,saldos!J$6) -> 0 | K11: =cuotas_emitidas!K6-SUMIFS(ingresos!$D:$D,ingresos!$F:$F,saldos!$A11,ingresos!$G:$G,saldos!K$6) -> 0 | ... Q11: =cuotas_emitidas!Q6-SUMIFS(ingresos!$D:$D,ingresos!$F:$F,saldos!$A11,ingresos!$G:$G,saldos!Q$6) -> 0 | R11: =SUM(D11:Q11) -> 0 | T11: =Q11 -> 0 | U11: =R11-T11 -> 0
A12: PP-005 | B12: ALVA CUELLAR DUGLAS CONCEPCION | C12: DEPA-1205 | D12: =cuotas_emitidas!D7-SUMIFS(ingresos!$D:$D,ingresos!$F:$F,saldos!$A12,ingresos!$G:$G,saldos!D$6) -> 0 | E12: =cuotas_emitidas!E7-SUMIFS(ingresos!$D:$D,ingresos!$F:$F,saldos!$A12,ingresos!$G:$G,saldos!E$6) -> 0 | F12: =cuotas_emitidas!F7-SUMIFS(ingresos!$D:$D,ingresos!$F:$F,saldos!$A12,ingresos!$G:$G,saldos!F$6) -> 0 | G12: =cuotas_emitidas!G7-SUMIFS(ingresos!$D:$D,ingresos!$F:$F,saldos!$A12,ingresos!$G:$G,saldos!G$6) -> 0 | H12: =cuotas_emitidas!H7-SUMIFS(ingresos!$D:$D,ingresos!$F:$F,saldos!$A12,ingresos!$G:$G,saldos!H$6) -> 0 | I12: =cuotas_emitidas!I7-SUMIFS(ingresos!$D:$D,ingresos!$F:$F,saldos!$A12,ingresos!$G:$G,saldos!I$6) -> 0 | J12: =cuotas_emitidas!J7-SUMIFS(ingresos!$D:$D,ingresos!$F:$F,saldos!$A12,ingresos!$G:$G,saldos!J$6) -> 0 | K12: =cuotas_emitidas!K7-SUMIFS(ingresos!$D:$D,ingresos!$F:$F,saldos!$A12,ingresos!$G:$G,saldos!K$6) -> 0 | ... Q12: =cuotas_emitidas!Q7-SUMIFS(ingresos!$D:$D,ingresos!$F:$F,saldos!$A12,ingresos!$G:$G,saldos!Q$6) -> 0 | R12: =SUM(D12:Q12) -> 0 | T12: =Q12 -> 0 | U12: =R12-T12 -> 0
A13: PP-006 | B13: ALVARADO BRINGAS MILUSKA CARLA | C13: DEPA-1001 | D13: =cuotas_emitidas!D8-SUMIFS(ingresos!$D:$D,ingresos!$F:$F,saldos!$A13,ingresos!$G:$G,saldos!D$6) -> 0 | E13: =cuotas_emitidas!E8-SUMIFS(ingresos!$D:$D,ingresos!$F:$F,saldos!$A13,ingresos!$G:$G,saldos!E$6) -> 0 | F13: =cuotas_emitidas!F8-SUMIFS(ingresos!$D:$D,ingresos!$F:$F,saldos!$A13,ingresos!$G:$G,saldos!F$6) -> 0 | G13: =cuotas_emitidas!G8-SUMIFS(ingresos!$D:$D,ingresos!$F:$F,saldos!$A13,ingresos!$G:$G,saldos!G$6) -> 0 | H13: =cuotas_emitidas!H8-SUMIFS(ingresos!$D:$D,ingresos!$F:$F,saldos!$A13,ingresos!$G:$G,saldos!H$6) -> 0 | I13: =cuotas_emitidas!I8-SUMIFS(ingresos!$D:$D,ingresos!$F:$F,saldos!$A13,ingresos!$G:$G,saldos!I$6) -> 0 | J13: =cuotas_emitidas!J8-SUMIFS(ingresos!$D:$D,ingresos!$F:$F,saldos!$A13,ingresos!$G:$G,saldos!J$6) -> 0 | K13: =cuotas_emitidas!K8-SUMIFS(ingresos!$D:$D,ingresos!$F:$F,saldos!$A13,ingresos!$G:$G,saldos!K$6) -> 0 | ... Q13: =cuotas_emitidas!Q8-SUMIFS(ingresos!$D:$D,ingresos!$F:$F,saldos!$A13,ingresos!$G:$G,saldos!Q$6) -> 534.14 | R13: =SUM(D13:Q13) -> 534.14 | T13: =Q13 -> 534.14 | U13: =R13-T13 -> 0
A14: PP-007 | B14: ANTON ENICE | C14: DEPA-610 | D14: =cuotas_emitidas!D9-SUMIFS(ingresos!$D:$D,ingresos!$F:$F,saldos!$A14,ingresos!$G:$G,saldos!D$6) -> 0 | E14: =cuotas_emitidas!E9-SUMIFS(ingresos!$D:$D,ingresos!$F:$F,saldos!$A14,ingresos!$G:$G,saldos!E$6) -> 0 | F14: =cuotas_emitidas!F9-SUMIFS(ingresos!$D:$D,ingresos!$F:$F,saldos!$A14,ingresos!$G:$G,saldos!F$6) -> 0 | G14: =cuotas_emitidas!G9-SUMIFS(ingresos!$D:$D,ingresos!$F:$F,saldos!$A14,ingresos!$G:$G,saldos!G$6) -> 0 | H14: =cuotas_emitidas!H9-SUMIFS(ingresos!$D:$D,ingresos!$F:$F,saldos!$A14,ingresos!$G:$G,saldos!H$6) -> 0 | I14: =cuotas_emitidas!I9-SUMIFS(ingresos!$D:$D,ingresos!$F:$F,saldos!$A14,ingresos!$G:$G,saldos!I$6) -> 0 | J14: =cuotas_emitidas!J9-SUMIFS(ingresos!$D:$D,ingresos!$F:$F,saldos!$A14,ingresos!$G:$G,saldos!J$6) -> 0 | K14: =cuotas_emitidas!K9-SUMIFS(ingresos!$D:$D,ingresos!$F:$F,saldos!$A14,ingresos!$G:$G,saldos!K$6) -> 0 | ... Q14: =cuotas_emitidas!Q9-SUMIFS(ingresos!$D:$D,ingresos!$F:$F,saldos!$A14,ingresos!$G:$G,saldos!Q$6) -> 318.57 | R14: =SUM(D14:Q14) -> 1913.57 | T14: =Q14 -> 318.57 | U14: =R14-T14 -> 1595
A15: PP-008 | B15: APARCANA ROSADIO LUIS MIGUEL | C15: DEPA-606 | D15: =cuotas_emitidas!D10-SUMIFS(ingresos!$D:$D,ingresos!$F:$F,saldos!$A15,ingresos!$G:$G,saldos!D$6) -> 0 | E15: =cuotas_emitidas!E10-SUMIFS(ingresos!$D:$D,ingresos!$F:$F,saldos!$A15,ingresos!$G:$G,saldos!E$6) -> 0 | F15: =cuotas_emitidas!F10-SUMIFS(ingresos!$D:$D,ingresos!$F:$F,saldos!$A15,ingresos!$G:$G,saldos!F$6) -> 0 | G15: =cuotas_emitidas!G10-SUMIFS(ingresos!$D:$D,ingresos!$F:$F,saldos!$A15,ingresos!$G:$G,saldos!G$6) -> 0 | H15: =cuotas_emitidas!H10-SUMIFS(ingresos!$D:$D,ingresos!$F:$F,saldos!$A15,ingresos!$G:$G,saldos!H$6) -> 0 | I15: =cuotas_emitidas!I10-SUMIFS(ingresos!$D:$D,ingresos!$F:$F,saldos!$A15,ingresos!$G:$G,saldos!I$6) -> 0 | J15: =cuotas_emitidas!J10-SUMIFS(ingresos!$D:$D,ingresos!$F:$F,saldos!$A15,ingresos!$G:$G,saldos!J$6) -> 0 | K15: =cuotas_emitidas!K10-SUMIFS(ingresos!$D:$D,ingresos!$F:$F,saldos!$A15,ingresos!$G:$G,saldos!K$6) -> 0 | ... Q15: =cuotas_emitidas!Q10-SUMIFS(ingresos!$D:$D,ingresos!$F:$F,saldos!$A15,ingresos!$G:$G,saldos!Q$6) -> 251.45 | R15: =SUM(D15:Q15) -> 251.45 | T15: =Q15 -> 251.45 | U15: =R15-T15 -> 0
A16: PP-009 | B16: ASTO VARGAS HANS PIERRE | C16: DEPA-1311 | D16: =cuotas_emitidas!D11-SUMIFS(ingresos!$D:$D,ingresos!$F:$F,saldos!$A16,ingresos!$G:$G,saldos!D$6) -> 0 | E16: =cuotas_emitidas!E11-SUMIFS(ingresos!$D:$D,ingresos!$F:$F,saldos!$A16,ingresos!$G:$G,saldos!E$6) -> 0 | F16: =cuotas_emitidas!F11-SUMIFS(ingresos!$D:$D,ingresos!$F:$F,saldos!$A16,ingresos!$G:$G,saldos!F$6) -> 0 | G16: =cuotas_emitidas!G11-SUMIFS(ingresos!$D:$D,ingresos!$F:$F,saldos!$A16,ingresos!$G:$G,saldos!G$6) -> 0 | H16: =cuotas_emitidas!H11-SUMIFS(ingresos!$D:$D,ingresos!$F:$F,saldos!$A16,ingresos!$G:$G,saldos!H$6) -> 0 | I16: =cuotas_emitidas!I11-SUMIFS(ingresos!$D:$D,ingresos!$F:$F,saldos!$A16,ingresos!$G:$G,saldos!I$6) -> 0 | J16: =cuotas_emitidas!J11-SUMIFS(ingresos!$D:$D,ingresos!$F:$F,saldos!$A16,ingresos!$G:$G,saldos!J$6) -> 0 | K16: =cuotas_emitidas!K11-SUMIFS(ingresos!$D:$D,ingresos!$F:$F,saldos!$A16,ingresos!$G:$G,saldos!K$6) -> 0 | ... Q16: =cuotas_emitidas!Q11-SUMIFS(ingresos!$D:$D,ingresos!$F:$F,saldos!$A16,ingresos!$G:$G,saldos!Q$6) -> 0 | R16: =SUM(D16:Q16) -> 3.34 | T16: =Q16 -> 0 | U16: =R16-T16 -> 3.34
A17: PP-010 | B17: AVENDAÑO SILVA MIRLEY JESUS | C17: ESTA-087 | D17: =cuotas_emitidas!D12-SUMIFS(ingresos!$D:$D,ingresos!$F:$F,saldos!$A17,ingresos!$G:$G,saldos!D$6) -> 0 | E17: =cuotas_emitidas!E12-SUMIFS(ingresos!$D:$D,ingresos!$F:$F,saldos!$A17,ingresos!$G:$G,saldos!E$6) -> 0 | F17: =cuotas_emitidas!F12-SUMIFS(ingresos!$D:$D,ingresos!$F:$F,saldos!$A17,ingresos!$G:$G,saldos!F$6) -> 0 | G17: =cuotas_emitidas!G12-SUMIFS(ingresos!$D:$D,ingresos!$F:$F,saldos!$A17,ingresos!$G:$G,saldos!G$6) -> 0 | H17: =cuotas_emitidas!H12-SUMIFS(ingresos!$D:$D,ingresos!$F:$F,saldos!$A17,ingresos!$G:$G,saldos!H$6) -> 0 | I17: =cuotas_emitidas!I12-SUMIFS(ingresos!$D:$D,ingresos!$F:$F,saldos!$A17,ingresos!$G:$G,saldos!I$6) -> 0 | J17: =cuotas_emitidas!J12-SUMIFS(ingresos!$D:$D,ingresos!$F:$F,saldos!$A17,ingresos!$G:$G,saldos!J$6) -> 0 | K17: =cuotas_emitidas!K12-SUMIFS(ingresos!$D:$D,ingresos!$F:$F,saldos!$A17,ingresos!$G:$G,saldos!K$6) -> 0 | ... Q17: =cuotas_emitidas!Q12-SUMIFS(ingresos!$D:$D,ingresos!$F:$F,saldos!$A17,ingresos!$G:$G,saldos!Q$6) -> 80.52 | R17: =SUM(D17:Q17) -> 241.56 | T17: =Q17 -> 80.52 | U17: =R17-T17 -> 161.04
A18: PP-011 | B18: AVILA JOEL ANTONIO | C18: DEPA-804 | D18: =cuotas_emitidas!D13-SUMIFS(ingresos!$D:$D,ingresos!$F:$F,saldos!$A18,ingresos!$G:$G,saldos!D$6) -> 0 | E18: =cuotas_emitidas!E13-SUMIFS(ingresos!$D:$D,ingresos!$F:$F,saldos!$A18,ingresos!$G:$G,saldos!E$6) -> 0 | F18: =cuotas_emitidas!F13-SUMIFS(ingresos!$D:$D,ingresos!$F:$F,saldos!$A18,ingresos!$G:$G,saldos!F$6) -> 0 | G18: =cuotas_emitidas!G13-SUMIFS(ingresos!$D:$D,ingresos!$F:$F,saldos!$A18,ingresos!$G:$G,saldos!G$6) -> 0 | H18: =cuotas_emitidas!H13-SUMIFS(ingresos!$D:$D,ingresos!$F:$F,saldos!$A18,ingresos!$G:$G,saldos!H$6) -> 0 | I18: =cuotas_emitidas!I13-SUMIFS(ingresos!$D:$D,ingresos!$F:$F,saldos!$A18,ingresos!$G:$G,saldos!I$6) -> 0 | J18: =cuotas_emitidas!J13-SUMIFS(ingresos!$D:$D,ingresos!$F:$F,saldos!$A18,ingresos!$G:$G,saldos!J$6) -> 0 | K18: =cuotas_emitidas!K13-SUMIFS(ingresos!$D:$D,ingresos!$F:$F,saldos!$A18,ingresos!$G:$G,saldos!K$6) -> 0 | ... Q18: =cuotas_emitidas!Q13-SUMIFS(ingresos!$D:$D,ingresos!$F:$F,saldos!$A18,ingresos!$G:$G,saldos!Q$6) -> 0 | R18: =SUM(D18:Q18) -> 0 | T18: =Q18 -> 0 | U18: =R18-T18 -> 0
... A210: PP-LAV | B210: LAVANDERIA PRONTOMATIK | C210: PP-LAV | D210: =cuotas_emitidas!D205-SUMIFS(ingresos!$D:$D,ingresos!$F:$F,saldos!$A210,ingresos!$G:$G,saldos!D$6) -> 0 | E210: =cuotas_emitidas!E205-SUMIFS(ingresos!$D:$D,ingresos!$F:$F,saldos!$A210,ingresos!$G:$G,saldos!E$6) -> 0 | F210: =cuotas_emitidas!F205-SUMIFS(ingresos!$D:$D,ingresos!$F:$F,saldos!$A210,ingresos!$G:$G,saldos!F$6) -> 0 | G210: =cuotas_emitidas!G205-SUMIFS(ingresos!$D:$D,ingresos!$F:$F,saldos!$A210,ingresos!$G:$G,saldos!G$6) -> 0 | H210: =cuotas_emitidas!H205-SUMIFS(ingresos!$D:$D,ingresos!$F:$F,saldos!$A210,ingresos!$G:$G,saldos!H$6) -> 0 | I210: =cuotas_emitidas!I205-SUMIFS(ingresos!$D:$D,ingresos!$F:$F,saldos!$A210,ingresos!$G:$G,saldos!I$6) -> 0 | J210: =cuotas_emitidas!J205-SUMIFS(ingresos!$D:$D,ingresos!$F:$F,saldos!$A210,ingresos!$G:$G,saldos!J$6) -> 0 | K210: =cuotas_emitidas!K205-SUMIFS(ingresos!$D:$D,ingresos!$F:$F,saldos!$A210,ingresos!$G:$G,saldos!K$6) -> 0 | ... Q210: =cuotas_emitidas!Q205-SUMIFS(ingresos!$D:$D,ingresos!$F:$F,saldos!$A210,ingresos!$G:$G,saldos!Q$6) -> 0 | R210: =SUM(D210:Q210) -> 437.12 | T210: =Q210 -> 0 | U210: =R210-T210 -> 437.12
D211: =SUM(D7:D210) -> 1099.8 | E211: =SUM(E7:E210) -> 3717.73 | F211: =SUM(F7:F210) -> 302.58 | G211: =SUM(G7:G210) -> 305.64 | H211: =SUM(H7:H210) -> 309.7 | I211: =SUM(I7:I210) -> 599.71 | J211: =SUM(J7:J210) -> 1716.01 | K211: =SUM(K7:K210) -> 2000.11 | ... R211: =SUM(R7:R210) -> 94395.33 | T211: =SUBTOTAL(9,T6:T208) -> 39699.6 | U211: =SUBTOTAL(9,U6:U208) -> 53889.75

Sheet recibo_newP
A1: EDIFICIO MULTIFAMILIAR "PACIFIK OCEAN TOWER"
A2: Av. Bertolotto Negro 850 - San Miguel
A3: 20614642247
A5: RECIBO MANTENIMIENTO | H5: cuota del mes | I5: =VLOOKUP($I$8,RESUMEN_mes!$A:$E,5,0) -> 349.6281
A7: Periodo | C7: Fecha emisión | E7: Fecha vencimiento | G7: Consumo agua (m3) | I7: Codigo Propietario
A8: 2026-enero | C8: 46030 | E8: 46044 | G8: =IFERROR(VLOOKUP($C$21,consumo_agua!$A$7:$X$203,22,0),0) -> 1 | I8: =$D$18 -> PP-202
A10: Titular 1 | C10: =VLOOKUP($I$8,calculo!$A:$B,2,0) -> PALOMINO CRISTIAN
A12: Titular 2
A14: Arrendatario
C18: CODIGO | D18: PP-202
C20: Predio | D20: % PARTICIPACIÓN | E20: VALOR CUOTA S/. | F20: AGUA CONSUMO S/. | G20: SUMA
C21: DEPA-1303 | D21: 0.0044974 | E21: 270.3657 | F21: 2.9752 | G21: 273.3409
C22: ESTA-133 | D22: 0.001269 | E22: 76.287204 | F22: 0 | G22: 76.287204
C23: Total general | D23: 0.0057664 | E23: 346.6529 | F23: 2.9752 | G23: 349.6281
A37: Informacion historica: | D37: abonos recibidos
A38: cuotas emitidas | D38: codigo | E38: PP-000 | H38: saldo por cobrar al mes anterior
A39: periodos ant. | B39: =VLOOKUP($I$8,cuotas_emitidas!$A$1:$E$206,4,0)+VLOOKUP($I$8,cuotas_emitidas!$A$1:$E$206,5,0) -> 0 | H39: periodos ant. | I39: =VLOOKUP($I$8,saldos!$A$6:$R$211,4,0)+VLOOKUP($I$8,saldos!$A$6:$R$211,5,0) -> 0
A40: 45658 | B40: =VLOOKUP($I$8,cuotas_emitidas!$A$1:$R$206,6,0) -> 0 | D40: FECHA ABONO | E40: IMPORTE RECIBIDO | H40: 45658 | I40: =VLOOKUP($I$8,saldos!$A$6:$R$211,6,0) -> 0
A41: 45689 | B41: =VLOOKUP($I$8,cuotas_emitidas!$A$1:$R$206,7,0) -> 0 | D41: 45870 | E41: 0 | H41: 45689 | I41: =VLOOKUP($I$8,saldos!$A$6:$R$211,7,0) -> 0
A42: 45717 | B42: =VLOOKUP($I$8,cuotas_emitidas!$A$1:$R$206,8,0) -> 0 | D42: Total general | E42: 0 | H42: 45717 | I42: =VLOOKUP($I$8,saldos!$A$6:$R$211,8,0) -> 0
A43: 45748 | B43: =VLOOKUP($I$8,cuotas_emitidas!$A$1:$R$206,9,0) -> 0 | H43: 45748 | I43: =VLOOKUP($I$8,saldos!$A$6:$R$211,9,0) -> 0
A44: 45778 | B44: =VLOOKUP($I$8,cuotas_emitidas!$A$1:$R$206,10,0) -> 0 | H44: 45778 | I44: =VLOOKUP($I$8,saldos!$A$6:$R$211,10,0) -> 0
A45: 45809 | B45: =VLOOKUP($I$8,cuotas_emitidas!$A$1:$R$206,11,0) -> 0 | H45: 45809 | I45: =VLOOKUP($I$8,saldos!$A$6:$R$211,11,0) -> 0
A46: 45839 | B46: =VLOOKUP($I$8,cuotas_emitidas!$A$1:$R$206,12,0) -> 0 | H46: 45839 | I46: =VLOOKUP($I$8,saldos!$A$6:$R$211,12,0) -> 0
A47: 45870 | B47: =VLOOKUP($I$8,cuotas_emitidas!$A$1:$R$206,13,0) -> 0 | H47: 45870 | I47: =VLOOKUP($I$8,saldos!$A$6:$R$211,13,0) -> 0
A48: 45901 | B48: =VLOOKUP($I$8,cuotas_emitidas!$A$1:$R$206,14,0) -> 0 | H48: 45901 | I48: =VLOOKUP($I$8,saldos!$A$6:$R$211,14,0) -> 0
A49: 45931 | B49: =VLOOKUP($I$8,cuotas_emitidas!$A$1:$R$206,15,0) -> 0 | H49: 45931 | I49: =VLOOKUP($I$8,saldos!$A$6:$R$211,15,0) -> 0
A50: 45962 | B50: =VLOOKUP($I$8,cuotas_emitidas!$A$1:$R$206,16,0) -> 0 | H50: 45962 | I50: =VLOOKUP($I$8,saldos!$A$6:$R$211,16,0) -> 0
A51: 45992 | B51: =VLOOKUP($I$8,cuotas_emitidas!$A$1:$R$206,17,0) -> 368.86 | H51: 45992 | I51: =VLOOKUP($I$8,saldos!$A$6:$R$211,17,0) -> 368.86
B52: =SUM(B39:B51) -> 368.86 | I52: =SUM(I39:I51) -> 368.86
A54: Recibo digital elaborado por: | H54: =IF($I$52<0,"*saldo a favor del propietario","-") -> -
A55: ALGORITMO ADMIN
